Workbook

Sheet 🏠 Inicio
B3: 💰 ORGANIZADOR DE FINANZAS 2026
B7: Tu dinero, tu control
B10: Presupuesto · Gastos · Ingresos · Ahorro · Metas financieras

Sheet ⚙️ Configuración
B2: ⚙️ CONFIGURACIÓN 2026
B5: Personaliza tus categorías. Los sheets mensuales las usan automáticamente.
B7: 💸 GASTOS | D7: 💰 INGRESOS
B8: CATEGORÍA | C8: PRESUP. MENSUAL | D8: CATEGORÍA | E8: MONTO ESPERADO
B9: Arriendo / Dividendo | C9: 0 | D9: Sueldo neto | E9: 0
B10: Alimentación | C10: 0 | D10: Honorarios / Freelance | E10: 0
B11: Transporte | C11: 0 | D11: Arriendo recibido | E11: 0
B12: Servicios básicos | C12: 0 | D12: Inversiones | E12: 0
B13: Salud | C13: 0 | D13: Bonos / Comisiones | E13: 0
B14: Educación | C14: 0 | D14: Ventas | E14: 0
B15: Entretenimiento | C15: 0 | D15: Otros ingresos | E15: 0
B16: Ropa y calzado | C16: 0
B17: Restaurantes / Cafés | C17: 0
B18: Gym / Deporte | C18: 0
B19: Tecnología | C19: 0
B20: Cuidado personal | C20: 0
B21: Mascotas | C21: 0
B22: Regalos | C22: 0
B23: Ahorro | C23: 0
B24: Inversiones | C24: 0
B25: Otros | C25: 0

Sheet ENE
B2: ENERO 2026
B4: 💰 INGRESOS | C4: 💸 GASTOS | D4: 💾 AHORRO | E4: % AHORRO
B5: =SUMIF(F8:F200,"Ingreso",E8:E200) | C5: =SUMIF(F8:F200,"Gasto",E8:E200) | D5: =SUMIF(F8:F200,"Ingreso",E8:E200)-SUMIF(F8:F200,"Gasto",E8:E200) | E5: =IFERROR((SUMIF(F8:F200,"Ingreso",E8:E200)-SUMIF(F8:F200,"Gasto",E8:E200))/SUMIF(F8:F200,"Ingreso",E8:E200),0)
B7: 📝 REGISTRO DE TRANSACCIONES | I7: 📊 PRESUPUESTO vs REAL
B8: FECHA | C8: DESCRIPCIÓN | D8: CATEGORÍA | E8: MONTO | F8: TIPO | G8: ACUMULADO | I8: CATEGORÍA | J8: PRESUPUESTO | K8: REAL | L8: DIFERENCIA | M8: ESTADO
F9: Ingreso | G9: =IF(F9="Ingreso",E9,-E9) | I9: ='⚙️ Configuración'!B9 | J9: ='⚙️ Configuración'!C9 | K9: =SUMIF(D9:D48,I9,E9:E48) | L9: =J9-K9 | M9: =IF(L9>=0,"✅ OK","⚠️ Excedido")
F10: Gasto | G10: =IF(E10="",G9,IF(F10="Ingreso",G9+E10,G9-E10)) | I10: ='⚙️ Configuración'!B10 | J10: ='⚙️ Configuración'!C10 | K10: =SUMIF(D9:D48,I10,E9:E48) | L10: =J10-K10 | M10: =IF(L10>=0,"✅ OK","⚠️ Excedido")
F11: Gasto | G11: =IF(E11="",G10,IF(F11="Ingreso",G10+E11,G10-E11)) | I11: ='⚙️ Configuración'!B11 | J11: ='⚙️ Configuración'!C11 | K11: =SUMIF(D9:D48,I11,E9:E48) | L11: =J11-K11 | M11: =IF(L11>=0,"✅ OK","⚠️ Excedido")
F12: Gasto | G12: =IF(E12="",G11,IF(F12="Ingreso",G11+E12,G11-E12)) | I12: ='⚙️ Configuración'!B12 | J12: ='⚙️ Configuración'!C12 | K12: =SUMIF(D9:D48,I12,E9:E48) | L12: =J12-K12 | M12: =IF(L12>=0,"✅ OK","⚠️ Excedido")
F13: Gasto | G13: =IF(E13="",G12,IF(F13="Ingreso",G12+E13,G12-E13)) | I13: ='⚙️ Configuración'!B13 | J13: ='⚙️ Configuración'!C13 | K13: =SUMIF(D9:D48,I13,E9:E48) | L13: =J13-K13 | M13: =IF(L13>=0,"✅ OK","⚠️ Excedido")
F14: Gasto | G14: =IF(E14="",G13,IF(F14="Ingreso",G13+E14,G13-E14)) | I14: ='⚙️ Configuración'!B14 | J14: ='⚙️ Configuración'!C14 | K14: =SUMIF(D9:D48,I14,E9:E48) | L14: =J14-K14 | M14: =IF(L14>=0,"✅ OK","⚠️ Excedido")
F15: Gasto | G15: =IF(E15="",G14,IF(F15="Ingreso",G14+E15,G14-E15)) | I15: ='⚙️ Configuración'!B15 | J15: ='⚙️ Configuración'!C15 | K15: =SUMIF(D9:D48,I15,E9:E48) | L15: =J15-K15 | M15: =IF(L15>=0,"✅ OK","⚠️ Excedido")
F16: Gasto | G16: =IF(E16="",G15,IF(F16="Ingreso",G15+E16,G15-E16)) | I16: ='⚙️ Configuración'!B16 | J16: ='⚙️ Configuración'!C16 | K16: =SUMIF(D9:D48,I16,E9:E48) | L16: =J16-K16 | M16: =IF(L16>=0,"✅ OK","⚠️ Excedido")
F17: Gasto | G17: =IF(E17="",G16,IF(F17="Ingreso",G16+E17,G16-E17)) | I17: ='⚙️ Configuración'!B17 | J17: ='⚙️ Configuración'!C17 | K17: =SUMIF(D9:D48,I17,E9:E48) | L17: =J17-K17 | M17: =IF(L17>=0,"✅ OK","⚠️ Excedido")
F18: Gasto | G18: =IF(E18="",G17,IF(F18="Ingreso",G17+E18,G17-E18)) | I18: ='⚙️ Configuración'!B18 | J18: ='⚙️ Configuración'!C18 | K18: =SUMIF(D9:D48,I18,E9:E48) | L18: =J18-K18 | M18: =IF(L18>=0,"✅ OK","⚠️ Excedido")
F19: Gasto | G19: =IF(E19="",G18,IF(F19="Ingreso",G18+E19,G18-E19)) | I19: ='⚙️ Configuración'!B19 | J19: ='⚙️ Configuración'!C19 | K19: =SUMIF(D9:D48,I19,E9:E48) | L19: =J19-K19 | M19: =IF(L19>=0,"✅ OK","⚠️ Excedido")
F20: Gasto | G20: =IF(E20="",G19,IF(F20="Ingreso",G19+E20,G19-E20)) | I20: ='⚙️ Configuración'!B20 | J20: ='⚙️ Configuración'!C20 | K20: =SUMIF(D9:D48,I20,E9:E48) | L20: =J20-K20 | M20: =IF(L20>=0,"✅ OK","⚠️ Excedido")
F21: Gasto | G21: =IF(E21="",G20,IF(F21="Ingreso",G20+E21,G20-E21)) | I21: ='⚙️ Configuración'!B21 | J21: ='⚙️ Configuración'!C21 | K21: =SUMIF(D9:D48,I21,E9:E48) | L21: =J21-K21 | M21: =IF(L21>=0,"✅ OK","⚠️ Excedido")
F22: Gasto | G22: =IF(E22="",G21,IF(F22="Ingreso",G21+E22,G21-E22)) | I22: ='⚙️ Configuración'!B22 | J22: ='⚙️ Configuración'!C22 | K22: =SUMIF(D9:D48,I22,E9:E48) | L22: =J22-K22 | M22: =IF(L22>=0,"✅ OK","⚠️ Excedido")
F23: Gasto | G23: =IF(E23="",G22,IF(F23="Ingreso",G22+E23,G22-E23)) | I23: ='⚙️ Configuración'!B23 | J23: ='⚙️ Configuración'!C23 | K23: =SUMIF(D9:D48,I23,E9:E48) | L23: =J23-K23 | M23: =IF(L23>=0,"✅ OK","⚠️ Excedido")
F24: Gasto | G24: =IF(E24="",G23,IF(F24="Ingreso",G23+E24,G23-E24))
F25: Gasto | G25: =IF(E25="",G24,IF(F25="Ingreso",G24+E25,G24-E25))
F26: Gasto | G26: =IF(E26="",G25,IF(F26="Ingreso",G25+E26,G25-E26))
F27: Gasto | G27: =IF(E27="",G26,IF(F27="Ingreso",G26+E27,G26-E27))
F28: Gasto | G28: =IF(E28="",G27,IF(F28="Ingreso",G27+E28,G27-E28))
F29: Gasto | G29: =IF(E29="",G28,IF(F29="Ingreso",G28+E29,G28-E29))
F30: Gasto | G30: =IF(E30="",G29,IF(F30="Ingreso",G29+E30,G29-E30))
F31: Gasto | G31: =IF(E31="",G30,IF(F31="Ingreso",G30+E31,G30-E31))
F32: Gasto | G32: =IF(E32="",G31,IF(F32="Ingreso",G31+E32,G31-E32))
F33: Gasto | G33: =IF(E33="",G32,IF(F33="Ingreso",G32+E33,G32-E33))
F34: Gasto | G34: =IF(E34="",G33,IF(F34="Ingreso",G33+E34,G33-E34))
F35: Gasto | G35: =IF(E35="",G34,IF(F35="Ingreso",G34+E35,G34-E35))
... F48: Gasto | G48: =IF(E48="",G47,IF(F48="Ingreso",G47+E48,G47-E48))

Sheet FEB
B2: FEBRERO 2026
B4: 💰 INGRESOS | C4: 💸 GASTOS | D4: 💾 AHORRO | E4: % AHORRO
B5: =SUMIF(F8:F200,"Ingreso",E8:E200) | C5: =SUMIF(F8:F200,"Gasto",E8:E200) | D5: =SUMIF(F8:F200,"Ingreso",E8:E200)-SUMIF(F8:F200,"Gasto",E8:E200) | E5: =IFERROR((SUMIF(F8:F200,"Ingreso",E8:E200)-SUMIF(F8:F200,"Gasto",E8:E200))/SUMIF(F8:F200,"Ingreso",E8:E200),0)
B7: 📝 REGISTRO DE TRANSACCIONES | I7: 📊 PRESUPUESTO vs REAL
B8: FECHA | C8: DESCRIPCIÓN | D8: CATEGORÍA | E8: MONTO | F8: TIPO | G8: ACUMULADO | I8: CATEGORÍA | J8: PRESUPUESTO | K8: REAL | L8: DIFERENCIA | M8: ESTADO
F9: Ingreso | G9: =IF(F9="Ingreso",E9,-E9) | I9: ='⚙️ Configuración'!B9 | J9: ='⚙️ Configuración'!C9 | K9: =SUMIF(D9:D48,I9,E9:E48) | L9: =J9-K9 | M9: =IF(L9>=0,"✅ OK","⚠️ Excedido")
F10: Gasto | G10: =IF(E10="",G9,IF(F10="Ingreso",G9+E10,G9-E10)) | I10: ='⚙️ Configuración'!B10 | J10: ='⚙️ Configuración'!C10 | K10: =SUMIF(D9:D48,I10,E9:E48) | L10: =J10-K10 | M10: =IF(L10>=0,"✅ OK","⚠️ Excedido")
F11: Gasto | G11: =IF(E11="",G10,IF(F11="Ingreso",G10+E11,G10-E11)) | I11: ='⚙️ Configuración'!B11 | J11: ='⚙️ Configuración'!C11 | K11: =SUMIF(D9:D48,I11,E9:E48) | L11: =J11-K11 | M11: =IF(L11>=0,"✅ OK","⚠️ Excedido")
F12: Gasto | G12: =IF(E12="",G11,IF(F12="Ingreso",G11+E12,G11-E12)) | I12: ='⚙️ Configuración'!B12 | J12: ='⚙️ Configuración'!C12 | K12: =SUMIF(D9:D48,I12,E9:E48) | L12: =J12-K12 | M12: =IF(L12>=0,"✅ OK","⚠️ Excedido")
F13: Gasto | G13: =IF(E13="",G12,IF(F13="Ingreso",G12+E13,G12-E13)) | I13: ='⚙️ Configuración'!B13 | J13: ='⚙️ Configuración'!C13 | K13: =SUMIF(D9:D48,I13,E9:E48) | L13: =J13-K13 | M13: =IF(L13>=0,"✅ OK","⚠️ Excedido")
F14: Gasto | G14: =IF(E14="",G13,IF(F14="Ingreso",G13+E14,G13-E14)) | I14: ='⚙️ Configuración'!B14 | J14: ='⚙️ Configuración'!C14 | K14: =SUMIF(D9:D48,I14,E9:E48) | L14: =J14-K14 | M14: =IF(L14>=0,"✅ OK","⚠️ Excedido")
F15: Gasto | G15: =IF(E15="",G14,IF(F15="Ingreso",G14+E15,G14-E15)) | I15: ='⚙️ Configuración'!B15 | J15: ='⚙️ Configuración'!C15 | K15: =SUMIF(D9:D48,I15,E9:E48) | L15: =J15-K15 | M15: =IF(L15>=0,"✅ OK","⚠️ Excedido")
F16: Gasto | G16: =IF(E16="",G15,IF(F16="Ingreso",G15+E16,G15-E16)) | I16: ='⚙️ Configuración'!B16 | J16: ='⚙️ Configuración'!C16 | K16: =SUMIF(D9:D48,I16,E9:E48) | L16: =J16-K16 | M16: =IF(L16>=0,"✅ OK","⚠️ Excedido")
F17: Gasto | G17: =IF(E17="",G16,IF(F17="Ingreso",G16+E17,G16-E17)) | I17: ='⚙️ Configuración'!B17 | J17: ='⚙️ Configuración'!C17 | K17: =SUMIF(D9:D48,I17,E9:E48) | L17: =J17-K17 | M17: =IF(L17>=0,"✅ OK","⚠️ Excedido")
F18: Gasto | G18: =IF(E18="",G17,IF(F18="Ingreso",G17+E18,G17-E18)) | I18: ='⚙️ Configuración'!B18 | J18: ='⚙️ Configuración'!C18 | K18: =SUMIF(D9:D48,I18,E9:E48) | L18: =J18-K18 | M18: =IF(L18>=0,"✅ OK","⚠️ Excedido")
F19: Gasto | G19: =IF(E19="",G18,IF(F19="Ingreso",G18+E19,G18-E19)) | I19: ='⚙️ Configuración'!B19 | J19: ='⚙️ Configuración'!C19 | K19: =SUMIF(D9:D48,I19,E9:E48) | L19: =J19-K19 | M19: =IF(L19>=0,"✅ OK","⚠️ Excedido")
F20: Gasto | G20: =IF(E20="",G19,IF(F20="Ingreso",G19+E20,G19-E20)) | I20: ='⚙️ Configuración'!B20 | J20: ='⚙️ Configuración'!C20 | K20: =SUMIF(D9:D48,I20,E9:E48) | L20: =J20-K20 | M20: =IF(L20>=0,"✅ OK","⚠️ Excedido")
F21: Gasto | G21: =IF(E21="",G20,IF(F21="Ingreso",G20+E21,G20-E21)) | I21: ='⚙️ Configuración'!B21 | J21: ='⚙️ Configuración'!C21 | K21: =SUMIF(D9:D48,I21,E9:E48) | L21: =J21-K21 | M21: =IF(L21>=0,"✅ OK","⚠️ Excedido")
F22: Gasto | G22: =IF(E22="",G21,IF(F22="Ingreso",G21+E22,G21-E22)) | I22: ='⚙️ Configuración'!B22 | J22: ='⚙️ Configuración'!C22 | K22: =SUMIF(D9:D48,I22,E9:E48) | L22: =J22-K22 | M22: =IF(L22>=0,"✅ OK","⚠️ Excedido")
F23: Gasto | G23: =IF(E23="",G22,IF(F23="Ingreso",G22+E23,G22-E23)) | I23: ='⚙️ Configuración'!B23 | J23: ='⚙️ Configuración'!C23 | K23: =SUMIF(D9:D48,I23,E9:E48) | L23: =J23-K23 | M23: =IF(L23>=0,"✅ OK","⚠️ Excedido")
F24: Gasto | G24: =IF(E24="",G23,IF(F24="Ingreso",G23+E24,G23-E24))
F25: Gasto | G25: =IF(E25="",G24,IF(F25="Ingreso",G24+E25,G24-E25))
F26: Gasto | G26: =IF(E26="",G25,IF(F26="Ingreso",G25+E26,G25-E26))
F27: Gasto | G27: =IF(E27="",G26,IF(F27="Ingreso",G26+E27,G26-E27))
F28: Gasto | G28: =IF(E28="",G27,IF(F28="Ingreso",G27+E28,G27-E28))
F29: Gasto | G29: =IF(E29="",G28,IF(F29="Ingreso",G28+E29,G28-E29))
F30: Gasto | G30: =IF(E30="",G29,IF(F30="Ingreso",G29+E30,G29-E30))
F31: Gasto | G31: =IF(E31="",G30,IF(F31="Ingreso",G30+E31,G30-E31))
F32: Gasto | G32: =IF(E32="",G31,IF(F32="Ingreso",G31+E32,G31-E32))
F33: Gasto | G33: =IF(E33="",G32,IF(F33="Ingreso",G32+E33,G32-E33))
F34: Gasto | G34: =IF(E34="",G33,IF(F34="Ingreso",G33+E34,G33-E34))
F35: Gasto | G35: =IF(E35="",G34,IF(F35="Ingreso",G34+E35,G34-E35))
... F48: Gasto | G48: =IF(E48="",G47,IF(F48="Ingreso",G47+E48,G47-E48))

Sheet MAR
B2: MARZO 2026
B4: 💰 INGRESOS | C4: 💸 GASTOS | D4: 💾 AHORRO | E4: % AHORRO
B5: =SUMIF(F8:F200,"Ingreso",E8:E200) | C5: =SUMIF(F8:F200,"Gasto",E8:E200) | D5: =SUMIF(F8:F200,"Ingreso",E8:E200)-SUMIF(F8:F200,"Gasto",E8:E200) | E5: =IFERROR((SUMIF(F8:F200,"Ingreso",E8:E200)-SUMIF(F8:F200,"Gasto",E8:E200))/SUMIF(F8:F200,"Ingreso",E8:E200),0)
B7: 📝 REGISTRO DE TRANSACCIONES | I7: 📊 PRESUPUESTO vs REAL
B8: FECHA | C8: DESCRIPCIÓN | D8: CATEGORÍA | E8: MONTO | F8: TIPO | G8: ACUMULADO | I8: CATEGORÍA | J8: PRESUPUESTO | K8: REAL | L8: DIFERENCIA | M8: ESTADO
F9: Ingreso | G9: =IF(F9="Ingreso",E9,-E9) | I9: ='⚙️ Configuración'!B9 | J9: ='⚙️ Configuración'!C9 | K9: =SUMIF(D9:D48,I9,E9:E48) | L9: =J9-K9 | M9: =IF(L9>=0,"✅ OK","⚠️ Excedido")
F10: Gasto | G10: =IF(E10="",G9,IF(F10="Ingreso",G9+E10,G9-E10)) | I10: ='⚙️ Configuración'!B10 | J10: ='⚙️ Configuración'!C10 | K10: =SUMIF(D9:D48,I10,E9:E48) | L10: =J10-K10 | M10: =IF(L10>=0,"✅ OK","⚠️ Excedido")
F11: Gasto | G11: =IF(E11="",G10,IF(F11="Ingreso",G10+E11,G10-E11)) | I11: ='⚙️ Configuración'!B11 | J11: ='⚙️ Configuración'!C11 | K11: =SUMIF(D9:D48,I11,E9:E48) | L11: =J11-K11 | M11: =IF(L11>=0,"✅ OK","⚠️ Excedido")
F12: Gasto | G12: =IF(E12="",G11,IF(F12="Ingreso",G11+E12,G11-E12)) | I12: ='⚙️ Configuración'!B12 | J12: ='⚙️ Configuración'!C12 | K12: =SUMIF(D9:D48,I12,E9:E48) | L12: =J12-K12 | M12: =IF(L12>=0,"✅ OK","⚠️ Excedido")
F13: Gasto | G13: =IF(E13="",G12,IF(F13="Ingreso",G12+E13,G12-E13)) | I13: ='⚙️ Configuración'!B13 | J13: ='⚙️ Configuración'!C13 | K13: =SUMIF(D9:D48,I13,E9:E48) | L13: =J13-K13 | M13: =IF(L13>=0,"✅ OK","⚠️ Excedido")
F14: Gasto | G14: =IF(E14="",G13,IF(F14="Ingreso",G13+E14,G13-E14)) | I14: ='⚙️ Configuración'!B14 | J14: ='⚙️ Configuración'!C14 | K14: =SUMIF(D9:D48,I14,E9:E48) | L14: =J14-K14 | M14: =IF(L14>=0,"✅ OK","⚠️ Excedido")
F15: Gasto | G15: =IF(E15="",G14,IF(F15="Ingreso",G14+E15,G14-E15)) | I15: ='⚙️ Configuración'!B15 | J15: ='⚙️ Configuración'!C15 | K15: =SUMIF(D9:D48,I15,E9:E48) | L15: =J15-K15 | M15: =IF(L15>=0,"✅ OK","⚠️ Excedido")
F16: Gasto | G16: =IF(E16="",G15,IF(F16="Ingreso",G15+E16,G15-E16)) | I16: ='⚙️ Configuración'!B16 | J16: ='⚙️ Configuración'!C16 | K16: =SUMIF(D9:D48,I16,E9:E48) | L16: =J16-K16 | M16: =IF(L16>=0,"✅ OK","⚠️ Excedido")
F17: Gasto | G17: =IF(E17="",G16,IF(F17="Ingreso",G16+E17,G16-E17)) | I17: ='⚙️ Configuración'!B17 | J17: ='⚙️ Configuración'!C17 | K17: =SUMIF(D9:D48,I17,E9:E48) | L17: =J17-K17 | M17: =IF(L17>=0,"✅ OK","⚠️ Excedido")
F18: Gasto | G18: =IF(E18="",G17,IF(F18="Ingreso",G17+E18,G17-E18)) | I18: ='⚙️ Configuración'!B18 | J18: ='⚙️ Configuración'!C18 | K18: =SUMIF(D9:D48,I18,E9:E48) | L18: =J18-K18 | M18: =IF(L18>=0,"✅ OK","⚠️ Excedido")
F19: Gasto | G19: =IF(E19="",G18,IF(F19="Ingreso",G18+E19,G18-E19)) | I19: ='⚙️ Configuración'!B19 | J19: ='⚙️ Configuración'!C19 | K19: =SUMIF(D9:D48,I19,E9:E48) | L19: =J19-K19 | M19: =IF(L19>=0,"✅ OK","⚠️ Excedido")
F20: Gasto | G20: =IF(E20="",G19,IF(F20="Ingreso",G19+E20,G19-E20)) | I20: ='⚙️ Configuración'!B20 | J20: ='⚙️ Configuración'!C20 | K20: =SUMIF(D9:D48,I20,E9:E48) | L20: =J20-K20 | M20: =IF(L20>=0,"✅ OK","⚠️ Excedido")
F21: Gasto | G21: =IF(E21="",G20,IF(F21="Ingreso",G20+E21,G20-E21)) | I21: ='⚙️ Configuración'!B21 | J21: ='⚙️ Configuración'!C21 | K21: =SUMIF(D9:D48,I21,E9:E48) | L21: =J21-K21 | M21: =IF(L21>=0,"✅ OK","⚠️ Excedido")
F22: Gasto | G22: =IF(E22="",G21,IF(F22="Ingreso",G21+E22,G21-E22)) | I22: ='⚙️ Configuración'!B22 | J22: ='⚙️ Configuración'!C22 | K22: =SUMIF(D9:D48,I22,E9:E48) | L22: =J22-K22 | M22: =IF(L22>=0,"✅ OK","⚠️ Excedido")
F23: Gasto | G23: =IF(E23="",G22,IF(F23="Ingreso",G22+E23,G22-E23)) | I23: ='⚙️ Configuración'!B23 | J23: ='⚙️ Configuración'!C23 | K23: =SUMIF(D9:D48,I23,E9:E48) | L23: =J23-K23 | M23: =IF(L23>=0,"✅ OK","⚠️ Excedido")
F24: Gasto | G24: =IF(E24="",G23,IF(F24="Ingreso",G23+E24,G23-E24))
F25: Gasto | G25: =IF(E25="",G24,IF(F25="Ingreso",G24+E25,G24-E25))
F26: Gasto | G26: =IF(E26="",G25,IF(F26="Ingreso",G25+E26,G25-E26))
F27: Gasto | G27: =IF(E27="",G26,IF(F27="Ingreso",G26+E27,G26-E27))
F28: Gasto | G28: =IF(E28="",G27,IF(F28="Ingreso",G27+E28,G27-E28))
F29: Gasto | G29: =IF(E29="",G28,IF(F29="Ingreso",G28+E29,G28-E29))
F30: Gasto | G30: =IF(E30="",G29,IF(F30="Ingreso",G29+E30,G29-E30))
F31: Gasto | G31: =IF(E31="",G30,IF(F31="Ingreso",G30+E31,G30-E31))
F32: Gasto | G32: =IF(E32="",G31,IF(F32="Ingreso",G31+E32,G31-E32))
F33: Gasto | G33: =IF(E33="",G32,IF(F33="Ingreso",G32+E33,G32-E33))
F34: Gasto | G34: =IF(E34="",G33,IF(F34="Ingreso",G33+E34,G33-E34))
F35: Gasto | G35: =IF(E35="",G34,IF(F35="Ingreso",G34+E35,G34-E35))
... F48: Gasto | G48: =IF(E48="",G47,IF(F48="Ingreso",G47+E48,G47-E48))

Sheet ABR
B2: ABRIL 2026
B4: 💰 INGRESOS | C4: 💸 GASTOS | D4: 💾 AHORRO | E4: % AHORRO
B5: =SUMIF(F8:F200,"Ingreso",E8:E200) | C5: =SUMIF(F8:F200,"Gasto",E8:E200) | D5: =SUMIF(F8:F200,"Ingreso",E8:E200)-SUMIF(F8:F200,"Gasto",E8:E200) | E5: =IFERROR((SUMIF(F8:F200,"Ingreso",E8:E200)-SUMIF(F8:F200,"Gasto",E8:E200))/SUMIF(F8:F200,"Ingreso",E8:E200),0)
B7: 📝 REGISTRO DE TRANSACCIONES | I7: 📊 PRESUPUESTO vs REAL
B8: FECHA | C8: DESCRIPCIÓN | D8: CATEGORÍA | E8: MONTO | F8: TIPO | G8: ACUMULADO | I8: CATEGORÍA | J8: PRESUPUESTO | K8: REAL | L8: DIFERENCIA | M8: ESTADO
F9: Ingreso | G9: =IF(F9="Ingreso",E9,-E9) | I9: ='⚙️ Configuración'!B9 | J9: ='⚙️ Configuración'!C9 | K9: =SUMIF(D9:D48,I9,E9:E48) | L9: =J9-K9 | M9: =IF(L9>=0,"✅ OK","⚠️ Excedido")
F10: Gasto | G10: =IF(E10="",G9,IF(F10="Ingreso",G9+E10,G9-E10)) | I10: ='⚙️ Configuración'!B10 | J10: ='⚙️ Configuración'!C10 | K10: =SUMIF(D9:D48,I10,E9:E48) | L10: =J10-K10 | M10: =IF(L10>=0,"✅ OK","⚠️ Excedido")
F11: Gasto | G11: =IF(E11="",G10,IF(F11="Ingreso",G10+E11,G10-E11)) | I11: ='⚙️ Configuración'!B11 | J11: ='⚙️ Configuración'!C11 | K11: =SUMIF(D9:D48,I11,E9:E48) | L11: =J11-K11 | M11: =IF(L11>=0,"✅ OK","⚠️ Excedido")
F12: Gasto | G12: =IF(E12="",G11,IF(F12="Ingreso",G11+E12,G11-E12)) | I12: ='⚙️ Configuración'!B12 | J12: ='⚙️ Configuración'!C12 | K12: =SUMIF(D9:D48,I12,E9:E48) | L12: =J12-K12 | M12: =IF(L12>=0,"✅ OK","⚠️ Excedido")
F13: Gasto | G13: =IF(E13="",G12,IF(F13="Ingreso",G12+E13,G12-E13)) | I13: ='⚙️ Configuración'!B13 | J13: ='⚙️ Configuración'!C13 | K13: =SUMIF(D9:D48,I13,E9:E48) | L13: =J13-K13 | M13: =IF(L13>=0,"✅ OK","⚠️ Excedido")
F14: Gasto | G14: =IF(E14="",G13,IF(F14="Ingreso",G13+E14,G13-E14)) | I14: ='⚙️ Configuración'!B14 | J14: ='⚙️ Configuración'!C14 | K14: =SUMIF(D9:D48,I14,E9:E48) | L14: =J14-K14 | M14: =IF(L14>=0,"✅ OK","⚠️ Excedido")
F15: Gasto | G15: =IF(E15="",G14,IF(F15="Ingreso",G14+E15,G14-E15)) | I15: ='⚙️ Configuración'!B15 | J15: ='⚙️ Configuración'!C15 | K15: =SUMIF(D9:D48,I15,E9:E48) | L15: =J15-K15 | M15: =IF(L15>=0,"✅ OK","⚠️ Excedido")
F16: Gasto | G16: =IF(E16="",G15,IF(F16="Ingreso",G15+E16,G15-E16)) | I16: ='⚙️ Configuración'!B16 | J16: ='⚙️ Configuración'!C16 | K16: =SUMIF(D9:D48,I16,E9:E48) | L16: =J16-K16 | M16: =IF(L16>=0,"✅ OK","⚠️ Excedido")
F17: Gasto | G17: =IF(E17="",G16,IF(F17="Ingreso",G16+E17,G16-E17)) | I17: ='⚙️ Configuración'!B17 | J17: ='⚙️ Configuración'!C17 | K17: =SUMIF(D9:D48,I17,E9:E48) | L17: =J17-K17 | M17: =IF(L17>=0,"✅ OK","⚠️ Excedido")
F18: Gasto | G18: =IF(E18="",G17,IF(F18="Ingreso",G17+E18,G17-E18)) | I18: ='⚙️ Configuración'!B18 | J18: ='⚙️ Configuración'!C18 | K18: =SUMIF(D9:D48,I18,E9:E48) | L18: =J18-K18 | M18: =IF(L18>=0,"✅ OK","⚠️ Excedido")
F19: Gasto | G19: =IF(E19="",G18,IF(F19="Ingreso",G18+E19,G18-E19)) | I19: ='⚙️ Configuración'!B19 | J19: ='⚙️ Configuración'!C19 | K19: =SUMIF(D9:D48,I19,E9:E48) | L19: =J19-K19 | M19: =IF(L19>=0,"✅ OK","⚠️ Excedido")
F20: Gasto | G20: =IF(E20="",G19,IF(F20="Ingreso",G19+E20,G19-E20)) | I20: ='⚙️ Configuración'!B20 | J20: ='⚙️ Configuración'!C20 | K20: =SUMIF(D9:D48,I20,E9:E48) | L20: =J20-K20 | M20: =IF(L20>=0,"✅ OK","⚠️ Excedido")
F21: Gasto | G21: =IF(E21="",G20,IF(F21="Ingreso",G20+E21,G20-E21)) | I21: ='⚙️ Configuración'!B21 | J21: ='⚙️ Configuración'!C21 | K21: =SUMIF(D9:D48,I21,E9:E48) | L21: =J21-K21 | M21: =IF(L21>=0,"✅ OK","⚠️ Excedido")
F22: Gasto | G22: =IF(E22="",G21,IF(F22="Ingreso",G21+E22,G21-E22)) | I22: ='⚙️ Configuración'!B22 | J22: ='⚙️ Configuración'!C22 | K22: =SUMIF(D9:D48,I22,E9:E48) | L22: =J22-K22 | M22: =IF(L22>=0,"✅ OK","⚠️ Excedido")
F23: Gasto | G23: =IF(E23="",G22,IF(F23="Ingreso",G22+E23,G22-E23)) | I23: ='⚙️ Configuración'!B23 | J23: ='⚙️ Configuración'!C23 | K23: =SUMIF(D9:D48,I23,E9:E48) | L23: =J23-K23 | M23: =IF(L23>=0,"✅ OK","⚠️ Excedido")
F24: Gasto | G24: =IF(E24="",G23,IF(F24="Ingreso",G23+E24,G23-E24))
F25: Gasto | G25: =IF(E25="",G24,IF(F25="Ingreso",G24+E25,G24-E25))
F26: Gasto | G26: =IF(E26="",G25,IF(F26="Ingreso",G25+E26,G25-E26))
F27: Gasto | G27: =IF(E27="",G26,IF(F27="Ingreso",G26+E27,G26-E27))
F28: Gasto | G28: =IF(E28="",G27,IF(F28="Ingreso",G27+E28,G27-E28))
F29: Gasto | G29: =IF(E29="",G28,IF(F29="Ingreso",G28+E29,G28-E29))
F30: Gasto | G30: =IF(E30="",G29,IF(F30="Ingreso",G29+E30,G29-E30))
F31: Gasto | G31: =IF(E31="",G30,IF(F31="Ingreso",G30+E31,G30-E31))
F32: Gasto | G32: =IF(E32="",G31,IF(F32="Ingreso",G31+E32,G31-E32))
F33: Gasto | G33: =IF(E33="",G32,IF(F33="Ingreso",G32+E33,G32-E33))
F34: Gasto | G34: =IF(E34="",G33,IF(F34="Ingreso",G33+E34,G33-E34))
F35: Gasto | G35: =IF(E35="",G34,IF(F35="Ingreso",G34+E35,G34-E35))
... F48: Gasto | G48: =IF(E48="",G47,IF(F48="Ingreso",G47+E48,G47-E48))

Sheet MAY
B2: MAYO 2026
B4: 💰 INGRESOS | C4: 💸 GASTOS | D4: 💾 AHORRO | E4: % AHORRO
B5: =SUMIF(F8:F200,"Ingreso",E8:E200) | C5: =SUMIF(F8:F200,"Gasto",E8:E200) | D5: =SUMIF(F8:F200,"Ingreso",E8:E200)-SUMIF(F8:F200,"Gasto",E8:E200) | E5: =IFERROR((SUMIF(F8:F200,"Ingreso",E8:E200)-SUMIF(F8:F200,"Gasto",E8:E200))/SUMIF(F8:F200,"Ingreso",E8:E200),0)
B7: 📝 REGISTRO DE TRANSACCIONES | I7: 📊 PRESUPUESTO vs REAL
B8: FECHA | C8: DESCRIPCIÓN | D8: CATEGORÍA | E8: MONTO | F8: TIPO | G8: ACUMULADO | I8: CATEGORÍA | J8: PRESUPUESTO | K8: REAL | L8: DIFERENCIA | M8: ESTADO
F9: Ingreso | G9: =IF(F9="Ingreso",E9,-E9) | I9: ='⚙️ Configuración'!B9 | J9: ='⚙️ Configuración'!C9 | K9: =SUMIF(D9:D48,I9,E9:E48) | L9: =J9-K9 | M9: =IF(L9>=0,"✅ OK","⚠️ Excedido")
F10: Gasto | G10: =IF(E10="",G9,IF(F10="Ingreso",G9+E10,G9-E10)) | I10: ='⚙️ Configuración'!B10 | J10: ='⚙️ Configuración'!C10 | K10: =SUMIF(D9:D48,I10,E9:E48) | L10: =J10-K10 | M10: =IF(L10>=0,"✅ OK","⚠️ Excedido")
F11: Gasto | G11: =IF(E11="",G10,IF(F11="Ingreso",G10+E11,G10-E11)) | I11: ='⚙️ Configuración'!B11 | J11: ='⚙️ Configuración'!C11 | K11: =SUMIF(D9:D48,I11,E9:E48) | L11: =J11-K11 | M11: =IF(L11>=0,"✅ OK","⚠️ Excedido")
F12: Gasto | G12: =IF(E12="",G11,IF(F12="Ingreso",G11+E12,G11-E12)) | I12: ='⚙️ Configuración'!B12 | J12: ='⚙️ Configuración'!C12 | K12: =SUMIF(D9:D48,I12,E9:E48) | L12: =J12-K12 | M12: =IF(L12>=0,"✅ OK","⚠️ Excedido")
F13: Gasto | G13: =IF(E13="",G12,IF(F13="Ingreso",G12+E13,G12-E13)) | I13: ='⚙️ Configuración'!B13 | J13: ='⚙️ Configuración'!C13 | K13: =SUMIF(D9:D48,I13,E9:E48) | L13: =J13-K13 | M13: =IF(L13>=0,"✅ OK","⚠️ Excedido")
F14: Gasto | G14: =IF(E14="",G13,IF(F14="Ingreso",G13+E14,G13-E14)) | I14: ='⚙️ Configuración'!B14 | J14: ='⚙️ Configuración'!C14 | K14: =SUMIF(D9:D48,I14,E9:E48) | L14: =J14-K14 | M14: =IF(L14>=0,"✅ OK","⚠️ Excedido")
F15: Gasto | G15: =IF(E15="",G14,IF(F15="Ingreso",G14+E15,G14-E15)) | I15: ='⚙️ Configuración'!B15 | J15: ='⚙️ Configuración'!C15 | K15: =SUMIF(D9:D48,I15,E9:E48) | L15: =J15-K15 | M15: =IF(L15>=0,"✅ OK","⚠️ Excedido")
F16: Gasto | G16: =IF(E16="",G15,IF(F16="Ingreso",G15+E16,G15-E16)) | I16: ='⚙️ Configuración'!B16 | J16: ='⚙️ Configuración'!C16 | K16: =SUMIF(D9:D48,I16,E9:E48) | L16: =J16-K16 | M16: =IF(L16>=0,"✅ OK","⚠️ Excedido")
F17: Gasto | G17: =IF(E17="",G16,IF(F17="Ingreso",G16+E17,G16-E17)) | I17: ='⚙️ Configuración'!B17 | J17: ='⚙️ Configuración'!C17 | K17: =SUMIF(D9:D48,I17,E9:E48) | L17: =J17-K17 | M17: =IF(L17>=0,"✅ OK","⚠️ Excedido")
F18: Gasto | G18: =IF(E18="",G17,IF(F18="Ingreso",G17+E18,G17-E18)) | I18: ='⚙️ Configuración'!B18 | J18: ='⚙️ Configuración'!C18 | K18: =SUMIF(D9:D48,I18,E9:E48) | L18: =J18-K18 | M18: =IF(L18>=0,"✅ OK","⚠️ Excedido")
F19: Gasto | G19: =IF(E19="",G18,IF(F19="Ingreso",G18+E19,G18-E19)) | I19: ='⚙️ Configuración'!B19 | J19: ='⚙️ Configuración'!C19 | K19: =SUMIF(D9:D48,I19,E9:E48) | L19: =J19-K19 | M19: =IF(L19>=0,"✅ OK","⚠️ Excedido")
F20: Gasto | G20: =IF(E20="",G19,IF(F20="Ingreso",G19+E20,G19-E20)) | I20: ='⚙️ Configuración'!B20 | J20: ='⚙️ Configuración'!C20 | K20: =SUMIF(D9:D48,I20,E9:E48) | L20: =J20-K20 | M20: =IF(L20>=0,"✅ OK","⚠️ Excedido")
F21: Gasto | G21: =IF(E21="",G20,IF(F21="Ingreso",G20+E21,G20-E21)) | I21: ='⚙️ Configuración'!B21 | J21: ='⚙️ Configuración'!C21 | K21: =SUMIF(D9:D48,I21,E9:E48) | L21: =J21-K21 | M21: =IF(L21>=0,"✅ OK","⚠️ Excedido")
F22: Gasto | G22: =IF(E22="",G21,IF(F22="Ingreso",G21+E22,G21-E22)) | I22: ='⚙️ Configuración'!B22 | J22: ='⚙️ Configuración'!C22 | K22: =SUMIF(D9:D48,I22,E9:E48) | L22: =J22-K22 | M22: =IF(L22>=0,"✅ OK","⚠️ Excedido")
F23: Gasto | G23: =IF(E23="",G22,IF(F23="Ingreso",G22+E23,G22-E23)) | I23: ='⚙️ Configuración'!B23 | J23: ='⚙️ Configuración'!C23 | K23: =SUMIF(D9:D48,I23,E9:E48) | L23: =J23-K23 | M23: =IF(L23>=0,"✅ OK","⚠️ Excedido")
F24: Gasto | G24: =IF(E24="",G23,IF(F24="Ingreso",G23+E24,G23-E24))
F25: Gasto | G25: =IF(E25="",G24,IF(F25="Ingreso",G24+E25,G24-E25))
F26: Gasto | G26: =IF(E26="",G25,IF(F26="Ingreso",G25+E26,G25-E26))
F27: Gasto | G27: =IF(E27="",G26,IF(F27="Ingreso",G26+E27,G26-E27))
F28: Gasto | G28: =IF(E28="",G27,IF(F28="Ingreso",G27+E28,G27-E28))
F29: Gasto | G29: =IF(E29="",G28,IF(F29="Ingreso",G28+E29,G28-E29))
F30: Gasto | G30: =IF(E30="",G29,IF(F30="Ingreso",G29+E30,G29-E30))
F31: Gasto | G31: =IF(E31="",G30,IF(F31="Ingreso",G30+E31,G30-E31))
F32: Gasto | G32: =IF(E32="",G31,IF(F32="Ingreso",G31+E32,G31-E32))
F33: Gasto | G33: =IF(E33="",G32,IF(F33="Ingreso",G32+E33,G32-E33))
F34: Gasto | G34: =IF(E34="",G33,IF(F34="Ingreso",G33+E34,G33-E34))
F35: Gasto | G35: =IF(E35="",G34,IF(F35="Ingreso",G34+E35,G34-E35))
... F48: Gasto | G48: =IF(E48="",G47,IF(F48="Ingreso",G47+E48,G47-E48))

Sheet JUN
B2: JUNIO 2026
B4: 💰 INGRESOS | C4: 💸 GASTOS | D4: 💾 AHORRO | E4: % AHORRO
B5: =SUMIF(F8:F200,"Ingreso",E8:E200) | C5: =SUMIF(F8:F200,"Gasto",E8:E200) | D5: =SUMIF(F8:F200,"Ingreso",E8:E200)-SUMIF(F8:F200,"Gasto",E8:E200) | E5: =IFERROR((SUMIF(F8:F200,"Ingreso",E8:E200)-SUMIF(F8:F200,"Gasto",E8:E200))/SUMIF(F8:F200,"Ingreso",E8:E200),0)
B7: 📝 REGISTRO DE TRANSACCIONES | I7: 📊 PRESUPUESTO vs REAL
B8: FECHA | C8: DESCRIPCIÓN | D8: CATEGORÍA | E8: MONTO | F8: TIPO | G8: ACUMULADO | I8: CATEGORÍA | J8: PRESUPUESTO | K8: REAL | L8: DIFERENCIA | M8: ESTADO
F9: Ingreso | G9: =IF(F9="Ingreso",E9,-E9) | I9: ='⚙️ Configuración'!B9 | J9: ='⚙️ Configuración'!C9 | K9: =SUMIF(D9:D48,I9,E9:E48) | L9: =J9-K9 | M9: =IF(L9>=0,"✅ OK","⚠️ Excedido")
F10: Gasto | G10: =IF(E10="",G9,IF(F10="Ingreso",G9+E10,G9-E10)) | I10: ='⚙️ Configuración'!B10 | J10: ='⚙️ Configuración'!C10 | K10: =SUMIF(D9:D48,I10,E9:E48) | L10: =J10-K10 | M10: =IF(L10>=0,"✅ OK","⚠️ Excedido")
F11: Gasto | G11: =IF(E11="",G10,IF(F11="Ingreso",G10+E11,G10-E11)) | I11: ='⚙️ Configuración'!B11 | J11: ='⚙️ Configuración'!C11 | K11: =SUMIF(D9:D48,I11,E9:E48) | L11: =J11-K11 | M11: =IF(L11>=0,"✅ OK","⚠️ Excedido")
F12: Gasto | G12: =IF(E12="",G11,IF(F12="Ingreso",G11+E12,G11-E12)) | I12: ='⚙️ Configuración'!B12 | J12: ='⚙️ Configuración'!C12 | K12: =SUMIF(D9:D48,I12,E9:E48) | L12: =J12-K12 | M12: =IF(L12>=0,"✅ OK","⚠️ Excedido")
F13: Gasto | G13: =IF(E13="",G12,IF(F13="Ingreso",G12+E13,G12-E13)) | I13: ='⚙️ Configuración'!B13 | J13: ='⚙️ Configuración'!C13 | K13: =SUMIF(D9:D48,I13,E9:E48) | L13: =J13-K13 | M13: =IF(L13>=0,"✅ OK","⚠️ Excedido")
F14: Gasto | G14: =IF(E14="",G13,IF(F14="Ingreso",G13+E14,G13-E14)) | I14: ='⚙️ Configuración'!B14 | J14: ='⚙️ Configuración'!C14 | K14: =SUMIF(D9:D48,I14,E9:E48) | L14: =J14-K14 | M14: =IF(L14>=0,"✅ OK","⚠️ Excedido")
F15: Gasto | G15: =IF(E15="",G14,IF(F15="Ingreso",G14+E15,G14-E15)) | I15: ='⚙️ Configuración'!B15 | J15: ='⚙️ Configuración'!C15 | K15: =SUMIF(D9:D48,I15,E9:E48) | L15: =J15-K15 | M15: =IF(L15>=0,"✅ OK","⚠️ Excedido")
F16: Gasto | G16: =IF(E16="",G15,IF(F16="Ingreso",G15+E16,G15-E16)) | I16: ='⚙️ Configuración'!B16 | J16: ='⚙️ Configuración'!C16 | K16: =SUMIF(D9:D48,I16,E9:E48) | L16: =J16-K16 | M16: =IF(L16>=0,"✅ OK","⚠️ Excedido")
F17: Gasto | G17: =IF(E17="",G16,IF(F17="Ingreso",G16+E17,G16-E17)) | I17: ='⚙️ Configuración'!B17 | J17: ='⚙️ Configuración'!C17 | K17: =SUMIF(D9:D48,I17,E9:E48) | L17: =J17-K17 | M17: =IF(L17>=0,"✅ OK","⚠️ Excedido")
F18: Gasto | G18: =IF(E18="",G17,IF(F18="Ingreso",G17+E18,G17-E18)) | I18: ='⚙️ Configuración'!B18 | J18: ='⚙️ Configuración'!C18 | K18: =SUMIF(D9:D48,I18,E9:E48) | L18: =J18-K18 | M18: =IF(L18>=0,"✅ OK","⚠️ Excedido")
F19: Gasto | G19: =IF(E19="",G18,IF(F19="Ingreso",G18+E19,G18-E19)) | I19: ='⚙️ Configuración'!B19 | J19: ='⚙️ Configuración'!C19 | K19: =SUMIF(D9:D48,I19,E9:E48) | L19: =J19-K19 | M19: =IF(L19>=0,"✅ OK","⚠️ Excedido")
F20: Gasto | G20: =IF(E20="",G19,IF(F20="Ingreso",G19+E20,G19-E20)) | I20: ='⚙️ Configuración'!B20 | J20: ='⚙️ Configuración'!C20 | K20: =SUMIF(D9:D48,I20,E9:E48) | L20: =J20-K20 | M20: =IF(L20>=0,"✅ OK","⚠️ Excedido")
F21: Gasto | G21: =IF(E21="",G20,IF(F21="Ingreso",G20+E21,G20-E21)) | I21: ='⚙️ Configuración'!B21 | J21: ='⚙️ Configuración'!C21 | K21: =SUMIF(D9:D48,I21,E9:E48) | L21: =J21-K21 | M21: =IF(L21>=0,"✅ OK","⚠️ Excedido")
F22: Gasto | G22: =IF(E22="",G21,IF(F22="Ingreso",G21+E22,G21-E22)) | I22: ='⚙️ Configuración'!B22 | J22: ='⚙️ Configuración'!C22 | K22: =SUMIF(D9:D48,I22,E9:E48) | L22: =J22-K22 | M22: =IF(L22>=0,"✅ OK","⚠️ Excedido")
F23: Gasto | G23: =IF(E23="",G22,IF(F23="Ingreso",G22+E23,G22-E23)) | I23: ='⚙️ Configuración'!B23 | J23: ='⚙️ Configuración'!C23 | K23: =SUMIF(D9:D48,I23,E9:E48) | L23: =J23-K23 | M23: =IF(L23>=0,"✅ OK","⚠️ Excedido")
F24: Gasto | G24: =IF(E24="",G23,IF(F24="Ingreso",G23+E24,G23-E24))
F25: Gasto | G25: =IF(E25="",G24,IF(F25="Ingreso",G24+E25,G24-E25))
F26: Gasto | G26: =IF(E26="",G25,IF(F26="Ingreso",G25+E26,G25-E26))
F27: Gasto | G27: =IF(E27="",G26,IF(F27="Ingreso",G26+E27,G26-E27))
F28: Gasto | G28: =IF(E28="",G27,IF(F28="Ingreso",G27+E28,G27-E28))
F29: Gasto | G29: =IF(E29="",G28,IF(F29="Ingreso",G28+E29,G28-E29))
F30: Gasto | G30: =IF(E30="",G29,IF(F30="Ingreso",G29+E30,G29-E30))
F31: Gasto | G31: =IF(E31="",G30,IF(F31="Ingreso",G30+E31,G30-E31))
F32: Gasto | G32: =IF(E32="",G31,IF(F32="Ingreso",G31+E32,G31-E32))
F33: Gasto | G33: =IF(E33="",G32,IF(F33="Ingreso",G32+E33,G32-E33))
F34: Gasto | G34: =IF(E34="",G33,IF(F34="Ingreso",G33+E34,G33-E34))
F35: Gasto | G35: =IF(E35="",G34,IF(F35="Ingreso",G34+E35,G34-E35))
... F48: Gasto | G48: =IF(E48="",G47,IF(F48="Ingreso",G47+E48,G47-E48))

Sheet JUL
B2: JULIO 2026
B4: 💰 INGRESOS | C4: 💸 GASTOS | D4: 💾 AHORRO | E4: % AHORRO
B5: =SUMIF(F8:F200,"Ingreso",E8:E200) | C5: =SUMIF(F8:F200,"Gasto",E8:E200) | D5: =SUMIF(F8:F200,"Ingreso",E8:E200)-SUMIF(F8:F200,"Gasto",E8:E200) | E5: =IFERROR((SUMIF(F8:F200,"Ingreso",E8:E200)-SUMIF(F8:F200,"Gasto",E8:E200))/SUMIF(F8:F200,"Ingreso",E8:E200),0)
B7: 📝 REGISTRO DE TRANSACCIONES | I7: 📊 PRESUPUESTO vs REAL
B8: FECHA | C8: DESCRIPCIÓN | D8: CATEGORÍA | E8: MONTO | F8: TIPO | G8: ACUMULADO | I8: CATEGORÍA | J8: PRESUPUESTO | K8: REAL | L8: DIFERENCIA | M8: ESTADO
F9: Ingreso | G9: =IF(F9="Ingreso",E9,-E9) | I9: ='⚙️ Configuración'!B9 | J9: ='⚙️ Configuración'!C9 | K9: =SUMIF(D9:D48,I9,E9:E48) | L9: =J9-K9 | M9: =IF(L9>=0,"✅ OK","⚠️ Excedido")
F10: Gasto | G10: =IF(E10="",G9,IF(F10="Ingreso",G9+E10,G9-E10)) | I10: ='⚙️ Configuración'!B10 | J10: ='⚙️ Configuración'!C10 | K10: =SUMIF(D9:D48,I10,E9:E48) | L10: =J10-K10 | M10: =IF(L10>=0,"✅ OK","⚠️ Excedido")
F11: Gasto | G11: =IF(E11="",G10,IF(F11="Ingreso",G10+E11,G10-E11)) | I11: ='⚙️ Configuración'!B11 | J11: ='⚙️ Configuración'!C11 | K11: =SUMIF(D9:D48,I11,E9:E48) | L11: =J11-K11 | M11: =IF(L11>=0,"✅ OK","⚠️ Excedido")
F12: Gasto | G12: =IF(E12="",G11,IF(F12="Ingreso",G11+E12,G11-E12)) | I12: ='⚙️ Configuración'!B12 | J12: ='⚙️ Configuración'!C12 | K12: =SUMIF(D9:D48,I12,E9:E48) | L12: =J12-K12 | M12: =IF(L12>=0,"✅ OK","⚠️ Excedido")
F13: Gasto | G13: =IF(E13="",G12,IF(F13="Ingreso",G12+E13,G12-E13)) | I13: ='⚙️ Configuración'!B13 | J13: ='⚙️ Configuración'!C13 | K13: =SUMIF(D9:D48,I13,E9:E48) | L13: =J13-K13 | M13: =IF(L13>=0,"✅ OK","⚠️ Excedido")
F14: Gasto | G14: =IF(E14="",G13,IF(F14="Ingreso",G13+E14,G13-E14)) | I14: ='⚙️ Configuración'!B14 | J14: ='⚙️ Configuración'!C14 | K14: =SUMIF(D9:D48,I14,E9:E48) | L14: =J14-K14 | M14: =IF(L14>=0,"✅ OK","⚠️ Excedido")
F15: Gasto | G15: =IF(E15="",G14,IF(F15="Ingreso",G14+E15,G14-E15)) | I15: ='⚙️ Configuración'!B15 | J15: ='⚙️ Configuración'!C15 | K15: =SUMIF(D9:D48,I15,E9:E48) | L15: =J15-K15 | M15: =IF(L15>=0,"✅ OK","⚠️ Excedido")
F16: Gasto | G16: =IF(E16="",G15,IF(F16="Ingreso",G15+E16,G15-E16)) | I16: ='⚙️ Configuración'!B16 | J16: ='⚙️ Configuración'!C16 | K16: =SUMIF(D9:D48,I16,E9:E48) | L16: =J16-K16 | M16: =IF(L16>=0,"✅ OK","⚠️ Excedido")
F17: Gasto | G17: =IF(E17="",G16,IF(F17="Ingreso",G16+E17,G16-E17)) | I17: ='⚙️ Configuración'!B17 | J17: ='⚙️ Configuración'!C17 | K17: =SUMIF(D9:D48,I17,E9:E48) | L17: =J17-K17 | M17: =IF(L17>=0,"✅ OK","⚠️ Excedido")
F18: Gasto | G18: =IF(E18="",G17,IF(F18="Ingreso",G17+E18,G17-E18)) | I18: ='⚙️ Configuración'!B18 | J18: ='⚙️ Configuración'!C18 | K18: =SUMIF(D9:D48,I18,E9:E48) | L18: =J18-K18 | M18: =IF(L18>=0,"✅ OK","⚠️ Excedido")
F19: Gasto | G19: =IF(E19="",G18,IF(F19="Ingreso",G18+E19,G18-E19)) | I19: ='⚙️ Configuración'!B19 | J19: ='⚙️ Configuración'!C19 | K19: =SUMIF(D9:D48,I19,E9:E48) | L19: =J19-K19 | M19: =IF(L19>=0,"✅ OK","⚠️ Excedido")
F20: Gasto | G20: =IF(E20="",G19,IF(F20="Ingreso",G19+E20,G19-E20)) | I20: ='⚙️ Configuración'!B20 | J20: ='⚙️ Configuración'!C20 | K20: =SUMIF(D9:D48,I20,E9:E48) | L20: =J20-K20 | M20: =IF(L20>=0,"✅ OK","⚠️ Excedido")
F21: Gasto | G21: =IF(E21="",G20,IF(F21="Ingreso",G20+E21,G20-E21)) | I21: ='⚙️ Configuración'!B21 | J21: ='⚙️ Configuración'!C21 | K21: =SUMIF(D9:D48,I21,E9:E48) | L21: =J21-K21 | M21: =IF(L21>=0,"✅ OK","⚠️ Excedido")
F22: Gasto | G22: =IF(E22="",G21,IF(F22="Ingreso",G21+E22,G21-E22)) | I22: ='⚙️ Configuración'!B22 | J22: ='⚙️ Configuración'!C22 | K22: =SUMIF(D9:D48,I22,E9:E48) | L22: =J22-K22 | M22: =IF(L22>=0,"✅ OK","⚠️ Excedido")
F23: Gasto | G23: =IF(E23="",G22,IF(F23="Ingreso",G22+E23,G22-E23)) | I23: ='⚙️ Configuración'!B23 | J23: ='⚙️ Configuración'!C23 | K23: =SUMIF(D9:D48,I23,E9:E48) | L23: =J23-K23 | M23: =IF(L23>=0,"✅ OK","⚠️ Excedido")
F24: Gasto | G24: =IF(E24="",G23,IF(F24="Ingreso",G23+E24,G23-E24))
F25: Gasto | G25: =IF(E25="",G24,IF(F25="Ingreso",G24+E25,G24-E25))
F26: Gasto | G26: =IF(E26="",G25,IF(F26="Ingreso",G25+E26,G25-E26))
F27: Gasto | G27: =IF(E27="",G26,IF(F27="Ingreso",G26+E27,G26-E27))
F28: Gasto | G28: =IF(E28="",G27,IF(F28="Ingreso",G27+E28,G27-E28))
F29: Gasto | G29: =IF(E29="",G28,IF(F29="Ingreso",G28+E29,G28-E29))
F30: Gasto | G30: =IF(E30="",G29,IF(F30="Ingreso",G29+E30,G29-E30))
F31: Gasto | G31: =IF(E31="",G30,IF(F31="Ingreso",G30+E31,G30-E31))
F32: Gasto | G32: =IF(E32="",G31,IF(F32="Ingreso",G31+E32,G31-E32))
F33: Gasto | G33: =IF(E33="",G32,IF(F33="Ingreso",G32+E33,G32-E33))
F34: Gasto | G34: =IF(E34="",G33,IF(F34="Ingreso",G33+E34,G33-E34))
F35: Gasto | G35: =IF(E35="",G34,IF(F35="Ingreso",G34+E35,G34-E35))
... F48: Gasto | G48: =IF(E48="",G47,IF(F48="Ingreso",G47+E48,G47-E48))

Sheet AGO
B2: AGOSTO 2026
B4: 💰 INGRESOS | C4: 💸 GASTOS | D4: 💾 AHORRO | E4: % AHORRO
B5: =SUMIF(F8:F200,"Ingreso",E8:E200) | C5: =SUMIF(F8:F200,"Gasto",E8:E200) | D5: =SUMIF(F8:F200,"Ingreso",E8:E200)-SUMIF(F8:F200,"Gasto",E8:E200) | E5: =IFERROR((SUMIF(F8:F200,"Ingreso",E8:E200)-SUMIF(F8:F200,"Gasto",E8:E200))/SUMIF(F8:F200,"Ingreso",E8:E200),0)
B7: 📝 REGISTRO DE TRANSACCIONES | I7: 📊 PRESUPUESTO vs REAL
B8: FECHA | C8: DESCRIPCIÓN | D8: CATEGORÍA | E8: MONTO | F8: TIPO | G8: ACUMULADO | I8: CATEGORÍA | J8: PRESUPUESTO | K8: REAL | L8: DIFERENCIA | M8: ESTADO
F9: Ingreso | G9: =IF(F9="Ingreso",E9,-E9) | I9: ='⚙️ Configuración'!B9 | J9: ='⚙️ Configuración'!C9 | K9: =SUMIF(D9:D48,I9,E9:E48) | L9: =J9-K9 | M9: =IF(L9>=0,"✅ OK","⚠️ Excedido")
F10: Gasto | G10: =IF(E10="",G9,IF(F10="Ingreso",G9+E10,G9-E10)) | I10: ='⚙️ Configuración'!B10 | J10: ='⚙️ Configuración'!C10 | K10: =SUMIF(D9:D48,I10,E9:E48) | L10: =J10-K10 | M10: =IF(L10>=0,"✅ OK","⚠️ Excedido")
F11: Gasto | G11: =IF(E11="",G10,IF(F11="Ingreso",G10+E11,G10-E11)) | I11: ='⚙️ Configuración'!B11 | J11: ='⚙️ Configuración'!C11 | K11: =SUMIF(D9:D48,I11,E9:E48) | L11: =J11-K11 | M11: =IF(L11>=0,"✅ OK","⚠️ Excedido")
F12: Gasto | G12: =IF(E12="",G11,IF(F12="Ingreso",G11+E12,G11-E12)) | I12: ='⚙️ Configuración'!B12 | J12: ='⚙️ Configuración'!C12 | K12: =SUMIF(D9:D48,I12,E9:E48) | L12: =J12-K12 | M12: =IF(L12>=0,"✅ OK","⚠️ Excedido")
F13: Gasto | G13: =IF(E13="",G12,IF(F13="Ingreso",G12+E13,G12-E13)) | I13: ='⚙️ Configuración'!B13 | J13: ='⚙️ Configuración'!C13 | K13: =SUMIF(D9:D48,I13,E9:E48) | L13: =J13-K13 | M13: =IF(L13>=0,"✅ OK","⚠️ Excedido")
F14: Gasto | G14: =IF(E14="",G13,IF(F14="Ingreso",G13+E14,G13-E14)) | I14: ='⚙️ Configuración'!B14 | J14: ='⚙️ Configuración'!C14 | K14: =SUMIF(D9:D48,I14,E9:E48) | L14: =J14-K14 | M14: =IF(L14>=0,"✅ OK","⚠️ Excedido")
F15: Gasto | G15: =IF(E15="",G14,IF(F15="Ingreso",G14+E15,G14-E15)) | I15: ='⚙️ Configuración'!B15 | J15: ='⚙️ Configuración'!C15 | K15: =SUMIF(D9:D48,I15,E9:E48) | L15: =J15-K15 | M15: =IF(L15>=0,"✅ OK","⚠️ Excedido")
F16: Gasto | G16: =IF(E16="",G15,IF(F16="Ingreso",G15+E16,G15-E16)) | I16: ='⚙️ Configuración'!B16 | J16: ='⚙️ Configuración'!C16 | K16: =SUMIF(D9:D48,I16,E9:E48) | L16: =J16-K16 | M16: =IF(L16>=0,"✅ OK","⚠️ Excedido")
F17: Gasto | G17: =IF(E17="",G16,IF(F17="Ingreso",G16+E17,G16-E17)) | I17: ='⚙️ Configuración'!B17 | J17: ='⚙️ Configuración'!C17 | K17: =SUMIF(D9:D48,I17,E9:E48) | L17: =J17-K17 | M17: =IF(L17>=0,"✅ OK","⚠️ Excedido")
F18: Gasto | G18: =IF(E18="",G17,IF(F18="Ingreso",G17+E18,G17-E18)) | I18: ='⚙️ Configuración'!B18 | J18: ='⚙️ Configuración'!C18 | K18: =SUMIF(D9:D48,I18,E9:E48) | L18: =J18-K18 | M18: =IF(L18>=0,"✅ OK","⚠️ Excedido")
F19: Gasto | G19: =IF(E19="",G18,IF(F19="Ingreso",G18+E19,G18-E19)) | I19: ='⚙️ Configuración'!B19 | J19: ='⚙️ Configuración'!C19 | K19: =SUMIF(D9:D48,I19,E9:E48) | L19: =J19-K19 | M19: =IF(L19>=0,"✅ OK","⚠️ Excedido")
F20: Gasto | G20: =IF(E20="",G19,IF(F20="Ingreso",G19+E20,G19-E20)) | I20: ='⚙️ Configuración'!B20 | J20: ='⚙️ Configuración'!C20 | K20: =SUMIF(D9:D48,I20,E9:E48) | L20: =J20-K20 | M20: =IF(L20>=0,"✅ OK","⚠️ Excedido")
F21: Gasto | G21: =IF(E21="",G20,IF(F21="Ingreso",G20+E21,G20-E21)) | I21: ='⚙️ Configuración'!B21 | J21: ='⚙️ Configuración'!C21 | K21: =SUMIF(D9:D48,I21,E9:E48) | L21: =J21-K21 | M21: =IF(L21>=0,"✅ OK","⚠️ Excedido")
F22: Gasto | G22: =IF(E22="",G21,IF(F22="Ingreso",G21+E22,G21-E22)) | I22: ='⚙️ Configuración'!B22 | J22: ='⚙️ Configuración'!C22 | K22: =SUMIF(D9:D48,I22,E9:E48) | L22: =J22-K22 | M22: =IF(L22>=0,"✅ OK","⚠️ Excedido")
F23: Gasto | G23: =IF(E23="",G22,IF(F23="Ingreso",G22+E23,G22-E23)) | I23: ='⚙️ Configuración'!B23 | J23: ='⚙️ Configuración'!C23 | K23: =SUMIF(D9:D48,I23,E9:E48) | L23: =J23-K23 | M23: =IF(L23>=0,"✅ OK","⚠️ Excedido")
F24: Gasto | G24: =IF(E24="",G23,IF(F24="Ingreso",G23+E24,G23-E24))
F25: Gasto | G25: =IF(E25="",G24,IF(F25="Ingreso",G24+E25,G24-E25))
F26: Gasto | G26: =IF(E26="",G25,IF(F26="Ingreso",G25+E26,G25-E26))
F27: Gasto | G27: =IF(E27="",G26,IF(F27="Ingreso",G26+E27,G26-E27))
F28: Gasto | G28: =IF(E28="",G27,IF(F28="Ingreso",G27+E28,G27-E28))
F29: Gasto | G29: =IF(E29="",G28,IF(F29="Ingreso",G28+E29,G28-E29))
F30: Gasto | G30: =IF(E30="",G29,IF(F30="Ingreso",G29+E30,G29-E30))
F31: Gasto | G31: =IF(E31="",G30,IF(F31="Ingreso",G30+E31,G30-E31))
F32: Gasto | G32: =IF(E32="",G31,IF(F32="Ingreso",G31+E32,G31-E32))
F33: Gasto | G33: =IF(E33="",G32,IF(F33="Ingreso",G32+E33,G32-E33))
F34: Gasto | G34: =IF(E34="",G33,IF(F34="Ingreso",G33+E34,G33-E34))
F35: Gasto | G35: =IF(E35="",G34,IF(F35="Ingreso",G34+E35,G34-E35))
... F48: Gasto | G48: =IF(E48="",G47,IF(F48="Ingreso",G47+E48,G47-E48))

Sheet SEP
B2: SEPTIEMBRE 2026
B4: 💰 INGRESOS | C4: 💸 GASTOS | D4: 💾 AHORRO | E4: % AHORRO
B5: =SUMIF(F8:F200,"Ingreso",E8:E200) | C5: =SUMIF(F8:F200,"Gasto",E8:E200) | D5: =SUMIF(F8:F200,"Ingreso",E8:E200)-SUMIF(F8:F200,"Gasto",E8:E200) | E5: =IFERROR((SUMIF(F8:F200,"Ingreso",E8:E200)-SUMIF(F8:F200,"Gasto",E8:E200))/SUMIF(F8:F200,"Ingreso",E8:E200),0)
B7: 📝 REGISTRO DE TRANSACCIONES | I7: 📊 PRESUPUESTO vs REAL
B8: FECHA | C8: DESCRIPCIÓN | D8: CATEGORÍA | E8: MONTO | F8: TIPO | G8: ACUMULADO | I8: CATEGORÍA | J8: PRESUPUESTO | K8: REAL | L8: DIFERENCIA | M8: ESTADO
F9: Ingreso | G9: =IF(F9="Ingreso",E9,-E9) | I9: ='⚙️ Configuración'!B9 | J9: ='⚙️ Configuración'!C9 | K9: =SUMIF(D9:D48,I9,E9:E48) | L9: =J9-K9 | M9: =IF(L9>=0,"✅ OK","⚠️ Excedido")
F10: Gasto | G10: =IF(E10="",G9,IF(F10="Ingreso",G9+E10,G9-E10)) | I10: ='⚙️ Configuración'!B10 | J10: ='⚙️ Configuración'!C10 | K10: =SUMIF(D9:D48,I10,E9:E48) | L10: =J10-K10 | M10: =IF(L10>=0,"✅ OK","⚠️ Excedido")
F11: Gasto | G11: =IF(E11="",G10,IF(F11="Ingreso",G10+E11,G10-E11)) | I11: ='⚙️ Configuración'!B11 | J11: ='⚙️ Configuración'!C11 | K11: =SUMIF(D9:D48,I11,E9:E48) | L11: =J11-K11 | M11: =IF(L11>=0,"✅ OK","⚠️ Excedido")
F12: Gasto | G12: =IF(E12="",G11,IF(F12="Ingreso",G11+E12,G11-E12)) | I12: ='⚙️ Configuración'!B12 | J12: ='⚙️ Configuración'!C12 | K12: =SUMIF(D9:D48,I12,E9:E48) | L12: =J12-K12 | M12: =IF(L12>=0,"✅ OK","⚠️ Excedido")
F13: Gasto | G13: =IF(E13="",G12,IF(F13="Ingreso",G12+E13,G12-E13)) | I13: ='⚙️ Configuración'!B13 | J13: ='⚙️ Configuración'!C13 | K13: =SUMIF(D9:D48,I13,E9:E48) | L13: =J13-K13 | M13: =IF(L13>=0,"✅ OK","⚠️ Excedido")
F14: Gasto | G14: =IF(E14="",G13,IF(F14="Ingreso",G13+E14,G13-E14)) | I14: ='⚙️ Configuración'!B14 | J14: ='⚙️ Configuración'!C14 | K14: =SUMIF(D9:D48,I14,E9:E48) | L14: =J14-K14 | M14: =IF(L14>=0,"✅ OK","⚠️ Excedido")
F15: Gasto | G15: =IF(E15="",G14,IF(F15="Ingreso",G14+E15,G14-E15)) | I15: ='⚙️ Configuración'!B15 | J15: ='⚙️ Configuración'!C15 | K15: =SUMIF(D9:D48,I15,E9:E48) | L15: =J15-K15 | M15: =IF(L15>=0,"✅ OK","⚠️ Excedido")
F16: Gasto | G16: =IF(E16="",G15,IF(F16="Ingreso",G15+E16,G15-E16)) | I16: ='⚙️ Configuración'!B16 | J16: ='⚙️ Configuración'!C16 | K16: =SUMIF(D9:D48,I16,E9:E48) | L16: =J16-K16 | M16: =IF(L16>=0,"✅ OK","⚠️ Excedido")
F17: Gasto | G17: =IF(E17="",G16,IF(F17="Ingreso",G16+E17,G16-E17)) | I17: ='⚙️ Configuración'!B17 | J17: ='⚙️ Configuración'!C17 | K17: =SUMIF(D9:D48,I17,E9:E48) | L17: =J17-K17 | M17: =IF(L17>=0,"✅ OK","⚠️ Excedido")
F18: Gasto | G18: =IF(E18="",G17,IF(F18="Ingreso",G17+E18,G17-E18)) | I18: ='⚙️ Configuración'!B18 | J18: ='⚙️ Configuración'!C18 | K18: =SUMIF(D9:D48,I18,E9:E48) | L18: =J18-K18 | M18: =IF(L18>=0,"✅ OK","⚠️ Excedido")
F19: Gasto | G19: =IF(E19="",G18,IF(F19="Ingreso",G18+E19,G18-E19)) | I19: ='⚙️ Configuración'!B19 | J19: ='⚙️ Configuración'!C19 | K19: =SUMIF(D9:D48,I19,E9:E48) | L19: =J19-K19 | M19: =IF(L19>=0,"✅ OK","⚠️ Excedido")
F20: Gasto | G20: =IF(E20="",G19,IF(F20="Ingreso",G19+E20,G19-E20)) | I20: ='⚙️ Configuración'!B20 | J20: ='⚙️ Configuración'!C20 | K20: =SUMIF(D9:D48,I20,E9:E48) | L20: =J20-K20 | M20: =IF(L20>=0,"✅ OK","⚠️ Excedido")
F21: Gasto | G21: =IF(E21="",G20,IF(F21="Ingreso",G20+E21,G20-E21)) | I21: ='⚙️ Configuración'!B21 | J21: ='⚙️ Configuración'!C21 | K21: =SUMIF(D9:D48,I21,E9:E48) | L21: =J21-K21 | M21: =IF(L21>=0,"✅ OK","⚠️ Excedido")
F22: Gasto | G22: =IF(E22="",G21,IF(F22="Ingreso",G21+E22,G21-E22)) | I22: ='⚙️ Configuración'!B22 | J22: ='⚙️ Configuración'!C22 | K22: =SUMIF(D9:D48,I22,E9:E48) | L22: =J22-K22 | M22: =IF(L22>=0,"✅ OK","⚠️ Excedido")
F23: Gasto | G23: =IF(E23="",G22,IF(F23="Ingreso",G22+E23,G22-E23)) | I23: ='⚙️ Configuración'!B23 | J23: ='⚙️ Configuración'!C23 | K23: =SUMIF(D9:D48,I23,E9:E48) | L23: =J23-K23 | M23: =IF(L23>=0,"✅ OK","⚠️ Excedido")
F24: Gasto | G24: =IF(E24="",G23,IF(F24="Ingreso",G23+E24,G23-E24))
F25: Gasto | G25: =IF(E25="",G24,IF(F25="Ingreso",G24+E25,G24-E25))
F26: Gasto | G26: =IF(E26="",G25,IF(F26="Ingreso",G25+E26,G25-E26))
F27: Gasto | G27: =IF(E27="",G26,IF(F27="Ingreso",G26+E27,G26-E27))
F28: Gasto | G28: =IF(E28="",G27,IF(F28="Ingreso",G27+E28,G27-E28))
F29: Gasto | G29: =IF(E29="",G28,IF(F29="Ingreso",G28+E29,G28-E29))
F30: Gasto | G30: =IF(E30="",G29,IF(F30="Ingreso",G29+E30,G29-E30))
F31: Gasto | G31: =IF(E31="",G30,IF(F31="Ingreso",G30+E31,G30-E31))
F32: Gasto | G32: =IF(E32="",G31,IF(F32="Ingreso",G31+E32,G31-E32))
F33: Gasto | G33: =IF(E33="",G32,IF(F33="Ingreso",G32+E33,G32-E33))
F34: Gasto | G34: =IF(E34="",G33,IF(F34="Ingreso",G33+E34,G33-E34))
F35: Gasto | G35: =IF(E35="",G34,IF(F35="Ingreso",G34+E35,G34-E35))
... F48: Gasto | G48: =IF(E48="",G47,IF(F48="Ingreso",G47+E48,G47-E48))

Sheet OCT
B2: OCTUBRE 2026
B4: 💰 INGRESOS | C4: 💸 GASTOS | D4: 💾 AHORRO | E4: % AHORRO
B5: =SUMIF(F8:F200,"Ingreso",E8:E200) | C5: =SUMIF(F8:F200,"Gasto",E8:E200) | D5: =SUMIF(F8:F200,"Ingreso",E8:E200)-SUMIF(F8:F200,"Gasto",E8:E200) | E5: =IFERROR((SUMIF(F8:F200,"Ingreso",E8:E200)-SUMIF(F8:F200,"Gasto",E8:E200))/SUMIF(F8:F200,"Ingreso",E8:E200),0)
B7: 📝 REGISTRO DE TRANSACCIONES | I7: 📊 PRESUPUESTO vs REAL
B8: FECHA | C8: DESCRIPCIÓN | D8: CATEGORÍA | E8: MONTO | F8: TIPO | G8: ACUMULADO | I8: CATEGORÍA | J8: PRESUPUESTO | K8: REAL | L8: DIFERENCIA | M8: ESTADO
F9: Ingreso | G9: =IF(F9="Ingreso",E9,-E9) | I9: ='⚙️ Configuración'!B9 | J9: ='⚙️ Configuración'!C9 | K9: =SUMIF(D9:D48,I9,E9:E48) | L9: =J9-K9 | M9: =IF(L9>=0,"✅ OK","⚠️ Excedido")
F10: Gasto | G10: =IF(E10="",G9,IF(F10="Ingreso",G9+E10,G9-E10)) | I10: ='⚙️ Configuración'!B10 | J10: ='⚙️ Configuración'!C10 | K10: =SUMIF(D9:D48,I10,E9:E48) | L10: =J10-K10 | M10: =IF(L10>=0,"✅ OK","⚠️ Excedido")
F11: Gasto | G11: =IF(E11="",G10,IF(F11="Ingreso",G10+E11,G10-E11)) | I11: ='⚙️ Configuración'!B11 | J11: ='⚙️ Configuración'!C11 | K11: =SUMIF(D9:D48,I11,E9:E48) | L11: =J11-K11 | M11: =IF(L11>=0,"✅ OK","⚠️ Excedido")
F12: Gasto | G12: =IF(E12="",G11,IF(F12="Ingreso",G11+E12,G11-E12)) | I12: ='⚙️ Configuración'!B12 | J12: ='⚙️ Configuración'!C12 | K12: =SUMIF(D9:D48,I12,E9:E48) | L12: =J12-K12 | M12: =IF(L12>=0,"✅ OK","⚠️ Excedido")
F13: Gasto | G13: =IF(E13="",G12,IF(F13="Ingreso",G12+E13,G12-E13)) | I13: ='⚙️ Configuración'!B13 | J13: ='⚙️ Configuración'!C13 | K13: =SUMIF(D9:D48,I13,E9:E48) | L13: =J13-K13 | M13: =IF(L13>=0,"✅ OK","⚠️ Excedido")
F14: Gasto | G14: =IF(E14="",G13,IF(F14="Ingreso",G13+E14,G13-E14)) | I14: ='⚙️ Configuración'!B14 | J14: ='⚙️ Configuración'!C14 | K14: =SUMIF(D9:D48,I14,E9:E48) | L14: =J14-K14 | M14: =IF(L14>=0,"✅ OK","⚠️ Excedido")
F15: Gasto | G15: =IF(E15="",G14,IF(F15="Ingreso",G14+E15,G14-E15)) | I15: ='⚙️ Configuración'!B15 | J15: ='⚙️ Configuración'!C15 | K15: =SUMIF(D9:D48,I15,E9:E48) | L15: =J15-K15 | M15: =IF(L15>=0,"✅ OK","⚠️ Excedido")
F16: Gasto | G16: =IF(E16="",G15,IF(F16="Ingreso",G15+E16,G15-E16)) | I16: ='⚙️ Configuración'!B16 | J16: ='⚙️ Configuración'!C16 | K16: =SUMIF(D9:D48,I16,E9:E48) | L16: =J16-K16 | M16: =IF(L16>=0,"✅ OK","⚠️ Excedido")
F17: Gasto | G17: =IF(E17="",G16,IF(F17="Ingreso",G16+E17,G16-E17)) | I17: ='⚙️ Configuración'!B17 | J17: ='⚙️ Configuración'!C17 | K17: =SUMIF(D9:D48,I17,E9:E48) | L17: =J17-K17 | M17: =IF(L17>=0,"✅ OK","⚠️ Excedido")
F18: Gasto | G18: =IF(E18="",G17,IF(F18="Ingreso",G17+E18,G17-E18)) | I18: ='⚙️ Configuración'!B18 | J18: ='⚙️ Configuración'!C18 | K18: =SUMIF(D9:D48,I18,E9:E48) | L18: =J18-K18 | M18: =IF(L18>=0,"✅ OK","⚠️ Excedido")
F19: Gasto | G19: =IF(E19="",G18,IF(F19="Ingreso",G18+E19,G18-E19)) | I19: ='⚙️ Configuración'!B19 | J19: ='⚙️ Configuración'!C19 | K19: =SUMIF(D9:D48,I19,E9:E48) | L19: =J19-K19 | M19: =IF(L19>=0,"✅ OK","⚠️ Excedido")
F20: Gasto | G20: =IF(E20="",G19,IF(F20="Ingreso",G19+E20,G19-E20)) | I20: ='⚙️ Configuración'!B20 | J20: ='⚙️ Configuración'!C20 | K20: =SUMIF(D9:D48,I20,E9:E48) | L20: =J20-K20 | M20: =IF(L20>=0,"✅ OK","⚠️ Excedido")
F21: Gasto | G21: =IF(E21="",G20,IF(F21="Ingreso",G20+E21,G20-E21)) | I21: ='⚙️ Configuración'!B21 | J21: ='⚙️ Configuración'!C21 | K21: =SUMIF(D9:D48,I21,E9:E48) | L21: =J21-K21 | M21: =IF(L21>=0,"✅ OK","⚠️ Excedido")
F22: Gasto | G22: =IF(E22="",G21,IF(F22="Ingreso",G21+E22,G21-E22)) | I22: ='⚙️ Configuración'!B22 | J22: ='⚙️ Configuración'!C22 | K22: =SUMIF(D9:D48,I22,E9:E48) | L22: =J22-K22 | M22: =IF(L22>=0,"✅ OK","⚠️ Excedido")
F23: Gasto | G23: =IF(E23="",G22,IF(F23="Ingreso",G22+E23,G22-E23)) | I23: ='⚙️ Configuración'!B23 | J23: ='⚙️ Configuración'!C23 | K23: =SUMIF(D9:D48,I23,E9:E48) | L23: =J23-K23 | M23: =IF(L23>=0,"✅ OK","⚠️ Excedido")
F24: Gasto | G24: =IF(E24="",G23,IF(F24="Ingreso",G23+E24,G23-E24))
F25: Gasto | G25: =IF(E25="",G24,IF(F25="Ingreso",G24+E25,G24-E25))
F26: Gasto | G26: =IF(E26="",G25,IF(F26="Ingreso",G25+E26,G25-E26))
F27: Gasto | G27: =IF(E27="",G26,IF(F27="Ingreso",G26+E27,G26-E27))
F28: Gasto | G28: =IF(E28="",G27,IF(F28="Ingreso",G27+E28,G27-E28))
F29: Gasto | G29: =IF(E29="",G28,IF(F29="Ingreso",G28+E29,G28-E29))
F30: Gasto | G30: =IF(E30="",G29,IF(F30="Ingreso",G29+E30,G29-E30))
F31: Gasto | G31: =IF(E31="",G30,IF(F31="Ingreso",G30+E31,G30-E31))
F32: Gasto | G32: =IF(E32="",G31,IF(F32="Ingreso",G31+E32,G31-E32))
F33: Gasto | G33: =IF(E33="",G32,IF(F33="Ingreso",G32+E33,G32-E33))
F34: Gasto | G34: =IF(E34="",G33,IF(F34="Ingreso",G33+E34,G33-E34))
F35: Gasto | G35: =IF(E35="",G34,IF(F35="Ingreso",G34+E35,G34-E35))
... F48: Gasto | G48: =IF(E48="",G47,IF(F48="Ingreso",G47+E48,G47-E48))

Sheet NOV
B2: NOVIEMBRE 2026
B4: 💰 INGRESOS | C4: 💸 GASTOS | D4: 💾 AHORRO | E4: % AHORRO
B5: =SUMIF(F8:F200,"Ingreso",E8:E200) | C5: =SUMIF(F8:F200,"Gasto",E8:E200) | D5: =SUMIF(F8:F200,"Ingreso",E8:E200)-SUMIF(F8:F200,"Gasto",E8:E200) | E5: =IFERROR((SUMIF(F8:F200,"Ingreso",E8:E200)-SUMIF(F8:F200,"Gasto",E8:E200))/SUMIF(F8:F200,"Ingreso",E8:E200),0)
B7: 📝 REGISTRO DE TRANSACCIONES | I7: 📊 PRESUPUESTO vs REAL
B8: FECHA | C8: DESCRIPCIÓN | D8: CATEGORÍA | E8: MONTO | F8: TIPO | G8: ACUMULADO | I8: CATEGORÍA | J8: PRESUPUESTO | K8: REAL | L8: DIFERENCIA | M8: ESTADO
F9: Ingreso | G9: =IF(F9="Ingreso",E9,-E9) | I9: ='⚙️ Configuración'!B9 | J9: ='⚙️ Configuración'!C9 | K9: =SUMIF(D9:D48,I9,E9:E48) | L9: =J9-K9 | M9: =IF(L9>=0,"✅ OK","⚠️ Excedido")
F10: Gasto | G10: =IF(E10="",G9,IF(F10="Ingreso",G9+E10,G9-E10)) | I10: ='⚙️ Configuración'!B10 | J10: ='⚙️ Configuración'!C10 | K10: =SUMIF(D9:D48,I10,E9:E48) | L10: =J10-K10 | M10: =IF(L10>=0,"✅ OK","⚠️ Excedido")
F11: Gasto | G11: =IF(E11="",G10,IF(F11="Ingreso",G10+E11,G10-E11)) | I11: ='⚙️ Configuración'!B11 | J11: ='⚙️ Configuración'!C11 | K11: =SUMIF(D9:D48,I11,E9:E48) | L11: =J11-K11 | M11: =IF(L11>=0,"✅ OK","⚠️ Excedido")
F12: Gasto | G12: =IF(E12="",G11,IF(F12="Ingreso",G11+E12,G11-E12)) | I12: ='⚙️ Configuración'!B12 | J12: ='⚙️ Configuración'!C12 | K12: =SUMIF(D9:D48,I12,E9:E48) | L12: =J12-K12 | M12: =IF(L12>=0,"✅ OK","⚠️ Excedido")
F13: Gasto | G13: =IF(E13="",G12,IF(F13="Ingreso",G12+E13,G12-E13)) | I13: ='⚙️ Configuración'!B13 | J13: ='⚙️ Configuración'!C13 | K13: =SUMIF(D9:D48,I13,E9:E48) | L13: =J13-K13 | M13: =IF(L13>=0,"✅ OK","⚠️ Excedido")
F14: Gasto | G14: =IF(E14="",G13,IF(F14="Ingreso",G13+E14,G13-E14)) | I14: ='⚙️ Configuración'!B14 | J14: ='⚙️ Configuración'!C14 | K14: =SUMIF(D9:D48,I14,E9:E48) | L14: =J14-K14 | M14: =IF(L14>=0,"✅ OK","⚠️ Excedido")
F15: Gasto | G15: =IF(E15="",G14,IF(F15="Ingreso",G14+E15,G14-E15)) | I15: ='⚙️ Configuración'!B15 | J15: ='⚙️ Configuración'!C15 | K15: =SUMIF(D9:D48,I15,E9:E48) | L15: =J15-K15 | M15: =IF(L15>=0,"✅ OK","⚠️ Excedido")
F16: Gasto | G16: =IF(E16="",G15,IF(F16="Ingreso",G15+E16,G15-E16)) | I16: ='⚙️ Configuración'!B16 | J16: ='⚙️ Configuración'!C16 | K16: =SUMIF(D9:D48,I16,E9:E48) | L16: =J16-K16 | M16: =IF(L16>=0,"✅ OK","⚠️ Excedido")
F17: Gasto | G17: =IF(E17="",G16,IF(F17="Ingreso",G16+E17,G16-E17)) | I17: ='⚙️ Configuración'!B17 | J17: ='⚙️ Configuración'!C17 | K17: =SUMIF(D9:D48,I17,E9:E48) | L17: =J17-K17 | M17: =IF(L17>=0,"✅ OK","⚠️ Excedido")
F18: Gasto | G18: =IF(E18="",G17,IF(F18="Ingreso",G17+E18,G17-E18)) | I18: ='⚙️ Configuración'!B18 | J18: ='⚙️ Configuración'!C18 | K18: =SUMIF(D9:D48,I18,E9:E48) | L18: =J18-K18 | M18: =IF(L18>=0,"✅ OK","⚠️ Excedido")
F19: Gasto | G19: =IF(E19="",G18,IF(F19="Ingreso",G18+E19,G18-E19)) | I19: ='⚙️ Configuración'!B19 | J19: ='⚙️ Configuración'!C19 | K19: =SUMIF(D9:D48,I19,E9:E48) | L19: =J19-K19 | M19: =IF(L19>=0,"✅ OK","⚠️ Excedido")
F20: Gasto | G20: =IF(E20="",G19,IF(F20="Ingreso",G19+E20,G19-E20)) | I20: ='⚙️ Configuración'!B20 | J20: ='⚙️ Configuración'!C20 | K20: =SUMIF(D9:D48,I20,E9:E48) | L20: =J20-K20 | M20: =IF(L20>=0,"✅ OK","⚠️ Excedido")
F21: Gasto | G21: =IF(E21="",G20,IF(F21="Ingreso",G20+E21,G20-E21)) | I21: ='⚙️ Configuración'!B21 | J21: ='⚙️ Configuración'!C21 | K21: =SUMIF(D9:D48,I21,E9:E48) | L21: =J21-K21 | M21: =IF(L21>=0,"✅ OK","⚠️ Excedido")
F22: Gasto | G22: =IF(E22="",G21,IF(F22="Ingreso",G21+E22,G21-E22)) | I22: ='⚙️ Configuración'!B22 | J22: ='⚙️ Configuración'!C22 | K22: =SUMIF(D9:D48,I22,E9:E48) | L22: =J22-K22 | M22: =IF(L22>=0,"✅ OK","⚠️ Excedido")
F23: Gasto | G23: =IF(E23="",G22,IF(F23="Ingreso",G22+E23,G22-E23)) | I23: ='⚙️ Configuración'!B23 | J23: ='⚙️ Configuración'!C23 | K23: =SUMIF(D9:D48,I23,E9:E48) | L23: =J23-K23 | M23: =IF(L23>=0,"✅ OK","⚠️ Excedido")
F24: Gasto | G24: =IF(E24="",G23,IF(F24="Ingreso",G23+E24,G23-E24))
F25: Gasto | G25: =IF(E25="",G24,IF(F25="Ingreso",G24+E25,G24-E25))
F26: Gasto | G26: =IF(E26="",G25,IF(F26="Ingreso",G25+E26,G25-E26))
F27: Gasto | G27: =IF(E27="",G26,IF(F27="Ingreso",G26+E27,G26-E27))
F28: Gasto | G28: =IF(E28="",G27,IF(F28="Ingreso",G27+E28,G27-E28))
F29: Gasto | G29: =IF(E29="",G28,IF(F29="Ingreso",G28+E29,G28-E29))
F30: Gasto | G30: =IF(E30="",G29,IF(F30="Ingreso",G29+E30,G29-E30))
F31: Gasto | G31: =IF(E31="",G30,IF(F31="Ingreso",G30+E31,G30-E31))
F32: Gasto | G32: =IF(E32="",G31,IF(F32="Ingreso",G31+E32,G31-E32))
F33: Gasto | G33: =IF(E33="",G32,IF(F33="Ingreso",G32+E33,G32-E33))
F34: Gasto | G34: =IF(E34="",G33,IF(F34="Ingreso",G33+E34,G33-E34))
F35: Gasto | G35: =IF(E35="",G34,IF(F35="Ingreso",G34+E35,G34-E35))
... F48: Gasto | G48: =IF(E48="",G47,IF(F48="Ingreso",G47+E48,G47-E48))

Sheet DIC
B2: DICIEMBRE 2026
B4: 💰 INGRESOS | C4: 💸 GASTOS | D4: 💾 AHORRO | E4: % AHORRO
B5: =SUMIF(F8:F200,"Ingreso",E8:E200) | C5: =SUMIF(F8:F200,"Gasto",E8:E200) | D5: =SUMIF(F8:F200,"Ingreso",E8:E200)-SUMIF(F8:F200,"Gasto",E8:E200) | E5: =IFERROR((SUMIF(F8:F200,"Ingreso",E8:E200)-SUMIF(F8:F200,"Gasto",E8:E200))/SUMIF(F8:F200,"Ingreso",E8:E200),0)
B7: 📝 REGISTRO DE TRANSACCIONES | I7: 📊 PRESUPUESTO vs REAL
B8: FECHA | C8: DESCRIPCIÓN | D8: CATEGORÍA | E8: MONTO | F8: TIPO | G8: ACUMULADO | I8: CATEGORÍA | J8: PRESUPUESTO | K8: REAL | L8: DIFERENCIA | M8: ESTADO
F9: Ingreso | G9: =IF(F9="Ingreso",E9,-E9) | I9: ='⚙️ Configuración'!B9 | J9: ='⚙️ Configuración'!C9 | K9: =SUMIF(D9:D48,I9,E9:E48) | L9: =J9-K9 | M9: =IF(L9>=0,"✅ OK","⚠️ Excedido")
F10: Gasto | G10: =IF(E10="",G9,IF(F10="Ingreso",G9+E10,G9-E10)) | I10: ='⚙️ Configuración'!B10 | J10: ='⚙️ Configuración'!C10 | K10: =SUMIF(D9:D48,I10,E9:E48) | L10: =J10-K10 | M10: =IF(L10>=0,"✅ OK","⚠️ Excedido")
F11: Gasto | G11: =IF(E11="",G10,IF(F11="Ingreso",G10+E11,G10-E11)) | I11: ='⚙️ Configuración'!B11 | J11: ='⚙️ Configuración'!C11 | K11: =SUMIF(D9:D48,I11,E9:E48) | L11: =J11-K11 | M11: =IF(L11>=0,"✅ OK","⚠️ Excedido")
F12: Gasto | G12: =IF(E12="",G11,IF(F12="Ingreso",G11+E12,G11-E12)) | I12: ='⚙️ Configuración'!B12 | J12: ='⚙️ Configuración'!C12 | K12: =SUMIF(D9:D48,I12,E9:E48) | L12: =J12-K12 | M12: =IF(L12>=0,"✅ OK","⚠️ Excedido")
F13: Gasto | G13: =IF(E13="",G12,IF(F13="Ingreso",G12+E13,G12-E13)) | I13: ='⚙️ Configuración'!B13 | J13: ='⚙️ Configuración'!C13 | K13: =SUMIF(D9:D48,I13,E9:E48) | L13: =J13-K13 | M13: =IF(L13>=0,"✅ OK","⚠️ Excedido")
F14: Gasto | G14: =IF(E14="",G13,IF(F14="Ingreso",G13+E14,G13-E14)) | I14: ='⚙️ Configuración'!B14 | J14: ='⚙️ Configuración'!C14 | K14: =SUMIF(D9:D48,I14,E9:E48) | L14: =J14-K14 | M14: =IF(L14>=0,"✅ OK","⚠️ Excedido")
F15: Gasto | G15: =IF(E15="",G14,IF(F15="Ingreso",G14+E15,G14-E15)) | I15: ='⚙️ Configuración'!B15 | J15: ='⚙️ Configuración'!C15 | K15: =SUMIF(D9:D48,I15,E9:E48) | L15: =J15-K15 | M15: =IF(L15>=0,"✅ OK","⚠️ Excedido")
F16: Gasto | G16: =IF(E16="",G15,IF(F16="Ingreso",G15+E16,G15-E16)) | I16: ='⚙️ Configuración'!B16 | J16: ='⚙️ Configuración'!C16 | K16: =SUMIF(D9:D48,I16,E9:E48) | L16: =J16-K16 | M16: =IF(L16>=0,"✅ OK","⚠️ Excedido")
F17: Gasto | G17: =IF(E17="",G16,IF(F17="Ingreso",G16+E17,G16-E17)) | I17: ='⚙️ Configuración'!B17 | J17: ='⚙️ Configuración'!C17 | K17: =SUMIF(D9:D48,I17,E9:E48) | L17: =J17-K17 | M17: =IF(L17>=0,"✅ OK","⚠️ Excedido")
F18: Gasto | G18: =IF(E18="",G17,IF(F18="Ingreso",G17+E18,G17-E18)) | I18: ='⚙️ Configuración'!B18 | J18: ='⚙️ Configuración'!C18 | K18: =SUMIF(D9:D48,I18,E9:E48) | L18: =J18-K18 | M18: =IF(L18>=0,"✅ OK","⚠️ Excedido")
F19: Gasto | G19: =IF(E19="",G18,IF(F19="Ingreso",G18+E19,G18-E19)) | I19: ='⚙️ Configuración'!B19 | J19: ='⚙️ Configuración'!C19 | K19: =SUMIF(D9:D48,I19,E9:E48) | L19: =J19-K19 | M19: =IF(L19>=0,"✅ OK","⚠️ Excedido")
F20: Gasto | G20: =IF(E20="",G19,IF(F20="Ingreso",G19+E20,G19-E20)) | I20: ='⚙️ Configuración'!B20 | J20: ='⚙️ Configuración'!C20 | K20: =SUMIF(D9:D48,I20,E9:E48) | L20: =J20-K20 | M20: =IF(L20>=0,"✅ OK","⚠️ Excedido")
F21: Gasto | G21: =IF(E21="",G20,IF(F21="Ingreso",G20+E21,G20-E21)) | I21: ='⚙️ Configuración'!B21 | J21: ='⚙️ Configuración'!C21 | K21: =SUMIF(D9:D48,I21,E9:E48) | L21: =J21-K21 | M21: =IF(L21>=0,"✅ OK","⚠️ Excedido")
F22: Gasto | G22: =IF(E22="",G21,IF(F22="Ingreso",G21+E22,G21-E22)) | I22: ='⚙️ Configuración'!B22 | J22: ='⚙️ Configuración'!C22 | K22: =SUMIF(D9:D48,I22,E9:E48) | L22: =J22-K22 | M22: =IF(L22>=0,"✅ OK","⚠️ Excedido")
F23: Gasto | G23: =IF(E23="",G22,IF(F23="Ingreso",G22+E23,G22-E23)) | I23: ='⚙️ Configuración'!B23 | J23: ='⚙️ Configuración'!C23 | K23: =SUMIF(D9:D48,I23,E9:E48) | L23: =J23-K23 | M23: =IF(L23>=0,"✅ OK","⚠️ Excedido")
F24: Gasto | G24: =IF(E24="",G23,IF(F24="Ingreso",G23+E24,G23-E24))
F25: Gasto | G25: =IF(E25="",G24,IF(F25="Ingreso",G24+E25,G24-E25))
F26: Gasto | G26: =IF(E26="",G25,IF(F26="Ingreso",G25+E26,G25-E26))
F27: Gasto | G27: =IF(E27="",G26,IF(F27="Ingreso",G26+E27,G26-E27))
F28: Gasto | G28: =IF(E28="",G27,IF(F28="Ingreso",G27+E28,G27-E28))
F29: Gasto | G29: =IF(E29="",G28,IF(F29="Ingreso",G28+E29,G28-E29))
F30: Gasto | G30: =IF(E30="",G29,IF(F30="Ingreso",G29+E30,G29-E30))
F31: Gasto | G31: =IF(E31="",G30,IF(F31="Ingreso",G30+E31,G30-E31))
F32: Gasto | G32: =IF(E32="",G31,IF(F32="Ingreso",G31+E32,G31-E32))
F33: Gasto | G33: =IF(E33="",G32,IF(F33="Ingreso",G32+E33,G32-E33))
F34: Gasto | G34: =IF(E34="",G33,IF(F34="Ingreso",G33+E34,G33-E34))
F35: Gasto | G35: =IF(E35="",G34,IF(F35="Ingreso",G34+E35,G34-E35))
... F48: Gasto | G48: =IF(E48="",G47,IF(F48="Ingreso",G47+E48,G47-E48))

Sheet 📊 Resumen Anual
B2: 📊 RESUMEN ANUAL 2026
B6: CONCEPTO | C6: ENE | D6: FEB | E6: MAR | F6: ABR | G6: MAY | H6: JUN | I6: JUL | J6: AGO | K6: SEP | L6: OCT | M6: NOV | N6: DIC | O6: TOTAL
B8: 💰 INGRESOS | C8: =SUMIF('ENE'!F9:F48,"Ingreso",'ENE'!E9:E48) | D8: =SUMIF('FEB'!F9:F48,"Ingreso",'FEB'!E9:E48) | E8: =SUMIF('MAR'!F9:F48,"Ingreso",'MAR'!E9:E48) | F8: =SUMIF('ABR'!F9:F48,"Ingreso",'ABR'!E9:E48) | G8: =SUMIF('MAY'!F9:F48,"Ingreso",'MAY'!E9:E48) | H8: =SUMIF('JUN'!F9:F48,"Ingreso",'JUN'!E9:E48) | I8: =SUMIF('JUL'!F9:F48,"Ingreso",'JUL'!E9:E48) | J8: =SUMIF('AGO'!F9:F48,"Ingreso",'AGO'!E9:E48) | K8: =SUMIF('SEP'!F9:F48,"Ingreso",'SEP'!E9:E48) | L8: =SUMIF('OCT'!F9:F48,"Ingreso",'OCT'!E9:E48) | M8: =SUMIF('NOV'!F9:F48,"Ingreso",'NOV'!E9:E48) | N8: =SUMIF('DIC'!F9:F48,"Ingreso",'DIC'!E9:E48) | O8: =SUM(C8:N8)
B9: 💸 GASTOS | C9: =SUMIF('ENE'!F9:F48,"Gasto",'ENE'!E9:E48) | D9: =SUMIF('FEB'!F9:F48,"Gasto",'FEB'!E9:E48) | E9: =SUMIF('MAR'!F9:F48,"Gasto",'MAR'!E9:E48) | F9: =SUMIF('ABR'!F9:F48,"Gasto",'ABR'!E9:E48) | G9: =SUMIF('MAY'!F9:F48,"Gasto",'MAY'!E9:E48) | H9: =SUMIF('JUN'!F9:F48,"Gasto",'JUN'!E9:E48) | I9: =SUMIF('JUL'!F9:F48,"Gasto",'JUL'!E9:E48) | J9: =SUMIF('AGO'!F9:F48,"Gasto",'AGO'!E9:E48) | K9: =SUMIF('SEP'!F9:F48,"Gasto",'SEP'!E9:E48) | L9: =SUMIF('OCT'!F9:F48,"Gasto",'OCT'!E9:E48) | M9: =SUMIF('NOV'!F9:F48,"Gasto",'NOV'!E9:E48) | N9: =SUMIF('DIC'!F9:F48,"Gasto",'DIC'!E9:E48) | O9: =SUM(C9:N9)
